Workbook

Sheet README
A1: McDonald's Azerbaijan – TikTok Ads: BEFORE vs AFTER analysis
A2: BEFORE = 1 Apr – 30 Jun 2026 (previous agency) · AFTER = 1 Jul – 30 Sep 2026 (current agency)
A4: Sources | B4: TikTok Ads Manager ad-level exports (USD): 'Tiktok_Ads_1_apr_-_30_June…20260401-20260630.xlsx' and 'Tiktok_Ads_1_july_-_Sep_30…20260701-20260930.xlsx'.
A5: Active ads | B5: Rows with zero spend (BEFORE 54, AFTER 83) have zero delivery; they are listed on 'Excluded rows' and left out of every calculation.
A6: Weighted KPIs | B6: All rates are recalculated from summed totals with live formulas (CPM = spend ÷ impressions × 1,000; CTR = clicks ÷ impressions; CPC = spend ÷ clicks; view rate = 2-sec views ÷ impressions). Row-level rates are never averaged.
A7: Unique reach | B7: TikTok's de-duplicated account reach comes from the 'Total of N results' row of each export (blue input on 'KPI Summary'). All other reach figures are ad-level reach summed, which counts a person once per ad.
A8: Objective | B8: Inferred from campaign names (Reach, Community interaction, Video views, App promotion) and from Results = Reach. Opening_Nizami Mall reports results ≠ reach and is labelled 'Unlabelled (results ≠ reach)'.
A9: Initiative | B9: Product keyword taken from the campaign name when it names a product, otherwise from the ad name (e.g. fifa, mixology, happy meal / HM, chicken / toyuq, cafe / cofe, grimace). Used only for like-for-like comparisons.
A10: Results | B10: The 'Results' column mixes unnamed result types by objective, so it is shown per row but never summed across objectives.
A11: Not in exports | B11: 6-sec views, likes, comments, shares, engagement rate, conversions, daily breakdown and placement split are not available.
A12: Colour code | B12: Blue text = values typed from the exports · black = formulas · green = links to another sheet · yellow fill = key KPI rows.
A13: Sheets | B13: KPI Summary · By Objective · Campaigns BEFORE / AFTER · Ad Groups BEFORE / AFTER · Like-for-like · Data BEFORE / AFTER (ads, with per-ad KPIs) · Validation · Excluded rows.

Sheet KPI Summary
A1: KPI summary – BEFORE vs AFTER
A2: Totals over active ads; rates recalculated from totals. Blue = input from the export's Total row.
A4: KPI | B4: BEFORE (Apr–Jun) | C4: AFTER (Jul–Sep) | D4: Absolute change | E4: % change | F4: Better when | G4: Verdict
A5: Amount spent (USD) | B5: =SUM('Data BEFORE'!$F$2:$F$48) -> 27255.89 | C5: =SUM('Data AFTER'!$F$2:$F$52) -> 24566.02 | D5: =C5-B5 -> -2689.87 | E5: =IFERROR((C5-B5)/B5,"") -> -0.098689494 | F5: Context | G5: =IF(F5="Context","Context",IF(OR(AND(F5="Higher",E5>0),AND(F5="Lower",E5<0)),"Improvement","Decline")) -> Context
A6: Unique reach (de-duplicated) | B6: 4928705 | C6: 5630553 | D6: =C6-B6 -> 701848 | E6: =IFERROR((C6-B6)/B6,"") -> 0.14240008 | F6: Higher | G6: =IF(F6="Context","Context",IF(OR(AND(F6="Higher",E6>0),AND(F6="Lower",E6<0)),"Improvement","Decline")) -> Improvement
A7: Impressions | B7: =SUM('Data BEFORE'!$H$2:$H$48) -> 105356739 | C7: =SUM('Data AFTER'!$H$2:$H$52) -> 93440992 | D7: =C7-B7 -> -11915747 | E7: =IFERROR((C7-B7)/B7,"") -> -0.11309905 | F7: Context | G7: =IF(F7="Context","Context",IF(OR(AND(F7="Higher",E7>0),AND(F7="Lower",E7<0)),"Improvement","Decline")) -> Context
A8: Frequency (impressions ÷ unique reach) | B8: =B7/B6 -> 21.37615 | C8: =C7/C6 -> 16.595349 | D8: =C8-B8 -> -4.7808013 | E8: =IFERROR((C8-B8)/B8,"") -> -0.22365118 | F8: Context | G8: =IF(F8="Context","Context",IF(OR(AND(F8="Higher",E8>0),AND(F8="Lower",E8<0)),"Improvement","Decline")) -> Context
A9: Cost per 1,000 unique reached (USD) | B9: =B5/B6*1000 -> 5.5300307 | C9: =C5/C6*1000 -> 4.3629853 | D9: =C9-B9 -> -1.1670454 | E9: =IFERROR((C9-B9)/B9,"") -> -0.21103778 | F9: Lower | G9: =IF(F9="Context","Context",IF(OR(AND(F9="Higher",E9>0),AND(F9="Lower",E9<0)),"Improvement","Decline")) -> Improvement
A10: CPM (USD) | B10: =B5/B7*1000 -> 0.25870096 | C10: =C5/C7*1000 -> 0.2629041 | D10: =C10-B10 -> 0.0042031365 | E10: =IFERROR((C10-B10)/B10,"") -> 0.016247085 | F10: Lower | G10: =IF(F10="Context","Context",IF(OR(AND(F10="Higher",E10>0),AND(F10="Lower",E10<0)),"Improvement","Decline")) -> Decline
A11: Clicks (destination) | B11: =SUM('Data BEFORE'!$I$2:$I$48) -> 246549 | C11: =SUM('Data AFTER'!$I$2:$I$52) -> 204396 | D11: =C11-B11 -> -42153 | E11: =IFERROR((C11-B11)/B11,"") -> -0.1709721 | F11: Higher | G11: =IF(F11="Context","Context",IF(OR(AND(F11="Higher",E11>0),AND(F11="Lower",E11<0)),"Improvement","Decline")) -> Decline
A12: CTR | B12: =B11/B7 -> 0.0023401351 | C12: =C11/C7 -> 0.002187434 | D12: =C12-B12 -> -0.0001527011 | E12: =IFERROR((C12-B12)/B12,"") -> -0.065253115 | F12: Higher | G12: =IF(F12="Context","Context",IF(OR(AND(F12="Higher",E12>0),AND(F12="Lower",E12<0)),"Improvement","Decline")) -> Decline
A13: CPC (USD) | B13: =B5/B11 -> 0.11054959 | C13: =C5/C11 -> 0.12018836 | D13: =C13-B13 -> 0.0096387734 | E13: =IFERROR((C13-B13)/B13,"") -> 0.087189592 | F13: Lower | G13: =IF(F13="Context","Context",IF(OR(AND(F13="Higher",E13>0),AND(F13="Lower",E13<0)),"Improvement","Decline")) -> Decline
A14: 2-sec video views | B14: =SUM('Data BEFORE'!$J$2:$J$48) -> 24143461 | C14: =SUM('Data AFTER'!$J$2:$J$52) -> 16912347 | D14: =C14-B14 -> -7231114 | E14: =IFERROR((C14-B14)/B14,"") -> -0.29950611 | F14: Higher | G14: =IF(F14="Context","Context",IF(OR(AND(F14="Higher",E14>0),AND(F14="Lower",E14<0)),"Improvement","Decline")) -> Decline
A15: 2-sec view rate | B15: =B14/B7 -> 0.22915915 | C15: =C14/C7 -> 0.18099494 | D15: =C15-B15 -> -0.04816421 | E15: =IFERROR((C15-B15)/B15,"") -> -0.21017799 | F15: Higher | G15: =IF(F15="Context","Context",IF(OR(AND(F15="Higher",E15>0),AND(F15="Lower",E15<0)),"Improvement","Decline")) -> Decline
A16: Cost per 1,000 2-sec views (USD) | B16: =B5/B14*1000 -> 1.128914 | C16: =C5/C14*1000 -> 1.4525494 | D16: =C16-B16 -> 0.32363548 | E16: =IFERROR((C16-B16)/B16,"") -> 0.2866786 | F16: Lower | G16: =IF(F16="Context","Context",IF(OR(AND(F16="Higher",E16>0),AND(F16="Lower",E16<0)),"Improvement","Decline")) -> Decline
A17: Reach (sum of ad-level reach) | B17: =SUM('Data BEFORE'!$G$2:$G$48) -> 65974915 | C17: =SUM('Data AFTER'!$G$2:$G$52) -> 61767357 | D17: =C17-B17 -> -4207558 | E17: =IFERROR((C17-B17)/B17,"") -> -0.063775118 | F17: Context | G17: =IF(F17="Context","Context",IF(OR(AND(F17="Higher",E17>0),AND(F17="Lower",E17<0)),"Improvement","Decline")) -> Context
A18: Cost per 1,000 reached – ad level (USD) | B18: =B5/B17*1000 -> 0.41312505 | C18: =C5/C17*1000 -> 0.39771849 | D18: =C18-B18 -> -0.015406558 | E18: =IFERROR((C18-B18)/B18,"") -> -0.037292724 | F18: Lower | G18: =IF(F18="Context","Context",IF(OR(AND(F18="Higher",E18>0),AND(F18="Lower",E18<0)),"Improvement","Decline")) -> Improvement
A19: Active ads | B19: =COUNTA('Data BEFORE'!$C$2:$C$48) -> 47 | C19: =COUNTA('Data AFTER'!$C$2:$C$52) -> 51 | D19: =C19-B19 -> 4 | E19: =IFERROR((C19-B19)/B19,"") -> 0.085106383 | F19: Context | G19: =IF(F19="Context","Context",IF(OR(AND(F19="Higher",E19>0),AND(F19="Lower",E19<0)),"Improvement","Decline")) -> Context
A21: Reading the table
A22: Spend fell ~10% while unique reach rose ~14%: cost per 1,000 unique people fell ~21% at an almost flat CPM – a genuine efficiency gain.
A23: Clicks (-17%) and 2-sec views (-30%) fell more than spend: CTR, CPC, view rate and cost per view all declined.
A24: Frequency is shown as context: lower means less repetition per person, not automatically better.

Sheet By Objective
A1: By objective – BEFORE vs AFTER
A2: Objective inferred from campaign names / results (see README). SUMIFS over the ad-level data.
A4: Objective | B4: Period | C4: Spend (USD) | D4: Share of spend | E4: Impressions | F4: Reach (ad level) | G4: Clicks | H4: 2-sec views | I4: CPM (USD) | J4: CTR | K4: CPC (USD) | L4: 2-sec view rate | M4: Cost / 1K 2-sec views (USD) | N4: Cost / 1K reached (USD)
A5: Reach | B5: BEFORE | C5: =SUMIFS('Data BEFORE'!$F$2:$F$48,'Data BEFORE'!$D$2:$D$48,$A5) -> 24996.83 | D5: =C5/SUM('Data BEFORE'!$F$2:$F$48) -> 0.91711663 | E5: =SUMIFS('Data BEFORE'!$H$2:$H$48,'Data BEFORE'!$D$2:$D$48,$A5) -> 101449829 | F5: =SUMIFS('Data BEFORE'!$G$2:$G$48,'Data BEFORE'!$D$2:$D$48,$A5) -> 64359864 | G5: =SUMIFS('Data BEFORE'!$I$2:$I$48,'Data BEFORE'!$D$2:$D$48,$A5) -> 246549 | H5: =SUMIFS('Data BEFORE'!$J$2:$J$48,'Data BEFORE'!$D$2:$D$48,$A5) -> 23235172 | I5: =IFERROR(C5/E5*1000,"") -> 0.24639598 | J5: =IFERROR(G5/E5,"") -> 0.0024302555 | K5: =IF(G5>0,C5/G5,"") -> 0.10138686 | L5: =IFERROR(H5/E5,"") -> 0.22903116 | M5: =IFERROR(C5/H5*1000,"") -> 1.0758186 | N5: =IFERROR(C5/F5*1000,"") -> 0.38839159
A6: Reach | B6: AFTER | C6: =SUMIFS('Data AFTER'!$F$2:$F$52,'Data AFTER'!$D$2:$D$52,$A6) -> 21656.15 | D6: =C6/SUM('Data AFTER'!$F$2:$F$52) -> 0.88154899 | E6: =SUMIFS('Data AFTER'!$H$2:$H$52,'Data AFTER'!$D$2:$D$52,$A6) -> 84266139 | F6: =SUMIFS('Data AFTER'!$G$2:$G$52,'Data AFTER'!$D$2:$D$52,$A6) -> 55562199 | G6: =SUMIFS('Data AFTER'!$I$2:$I$52,'Data AFTER'!$D$2:$D$52,$A6) -> 194229 | H6: =SUMIFS('Data AFTER'!$J$2:$J$52,'Data AFTER'!$D$2:$D$52,$A6) -> 13328155 | I6: =IFERROR(C6/E6*1000,"") -> 0.25699706 | J6: =IFERROR(G6/E6,"") -> 0.0023049472 | K6: =IF(G6>0,C6/G6,"") -> 0.11149803 | L6: =IFERROR(H6/E6,"") -> 0.15816739 | M6: =IFERROR(C6/H6*1000,"") -> 1.6248423 | N6: =IFERROR(C6/F6*1000,"") -> 0.38976409
A7: Video views | B7: BEFORE | C7: =SUMIFS('Data BEFORE'!$F$2:$F$48,'Data BEFORE'!$D$2:$D$48,$A7) -> 0 | D7: =C7/SUM('Data BEFORE'!$F$2:$F$48) -> 0 | E7: =SUMIFS('Data BEFORE'!$H$2:$H$48,'Data BEFORE'!$D$2:$D$48,$A7) -> 0 | F7: =SUMIFS('Data BEFORE'!$G$2:$G$48,'Data BEFORE'!$D$2:$D$48,$A7) -> 0 | G7: =SUMIFS('Data BEFORE'!$I$2:$I$48,'Data BEFORE'!$D$2:$D$48,$A7) -> 0 | H7: =SUMIFS('Data BEFORE'!$J$2:$J$48,'Data BEFORE'!$D$2:$D$48,$A7) -> 0 | I7: =IFERROR(C7/E7*1000,"") | J7: =IFERROR(G7/E7,"") | K7: =IF(G7>0,C7/G7,"") | L7: =IFERROR(H7/E7,"") | M7: =IFERROR(C7/H7*1000,"") | N7: =IFERROR(C7/F7*1000,"")
A8: Video views | B8: AFTER | C8: =SUMIFS('Data AFTER'!$F$2:$F$52,'Data AFTER'!$D$2:$D$52,$A8) -> 2115.28 | D8: =C8/SUM('Data AFTER'!$F$2:$F$52) -> 0.08610593 | E8: =SUMIFS('Data AFTER'!$H$2:$H$52,'Data AFTER'!$D$2:$D$52,$A8) -> 6629810 | F8: =SUMIFS('Data AFTER'!$G$2:$G$52,'Data AFTER'!$D$2:$D$52,$A8) -> 4947528 | G8: =SUMIFS('Data AFTER'!$I$2:$I$52,'Data AFTER'!$D$2:$D$52,$A8) -> 10050 | H8: =SUMIFS('Data AFTER'!$J$2:$J$52,'Data AFTER'!$D$2:$D$52,$A8) -> 2704406 | I8: =IFERROR(C8/E8*1000,"") -> 0.3190559 | J8: =IFERROR(G8/E8,"") -> 0.0015158805 | K8: =IF(G8>0,C8/G8,"") -> 0.21047562 | L8: =IFERROR(H8/E8,"") -> 0.40791606 | M8: =IFERROR(C8/H8*1000,"") -> 0.78216067 | N8: =IFERROR(C8/F8*1000,"") -> 0.42754281
A9: Community interaction | B9: BEFORE | C9: =SUMIFS('Data BEFORE'!$F$2:$F$48,'Data BEFORE'!$D$2:$D$48,$A9) -> 2259.06 | D9: =C9/SUM('Data BEFORE'!$F$2:$F$48) -> 0.082883369 | E9: =SUMIFS('Data BEFORE'!$H$2:$H$48,'Data BEFORE'!$D$2:$D$48,$A9) -> 3906910 | F9: =SUMIFS('Data BEFORE'!$G$2:$G$48,'Data BEFORE'!$D$2:$D$48,$A9) -> 1615051 | G9: =SUMIFS('Data BEFORE'!$I$2:$I$48,'Data BEFORE'!$D$2:$D$48,$A9) -> 0 | H9: =SUMIFS('Data BEFORE'!$J$2:$J$48,'Data BEFORE'!$D$2:$D$48,$A9) -> 908289 | I9: =IFERROR(C9/E9*1000,"") -> 0.57822166 | J9: =IFERROR(G9/E9,"") -> 0 | K9: =IF(G9>0,C9/G9,"") | L9: =IFERROR(H9/E9,"") -> 0.2324827 | M9: =IFERROR(C9/H9*1000,"") -> 2.4871599 | N9: =IFERROR(C9/F9*1000,"") -> 1.3987546
A10: Community interaction | B10: AFTER | C10: =SUMIFS('Data AFTER'!$F$2:$F$52,'Data AFTER'!$D$2:$D$52,$A10) -> 167.47 | D10: =C10/SUM('Data AFTER'!$F$2:$F$52) -> 0.0068171401 | E10: =SUMIFS('Data AFTER'!$H$2:$H$52,'Data AFTER'!$D$2:$D$52,$A10) -> 264593 | F10: =SUMIFS('Data AFTER'!$G$2:$G$52,'Data AFTER'!$D$2:$D$52,$A10) -> 130994 | G10: =SUMIFS('Data AFTER'!$I$2:$I$52,'Data AFTER'!$D$2:$D$52,$A10) -> 0 | H10: =SUMIFS('Data AFTER'!$J$2:$J$52,'Data AFTER'!$D$2:$D$52,$A10) -> 95236 | I10: =IFERROR(C10/E10*1000,"") -> 0.63293436 | J10: =IFERROR(G10/E10,"") -> 0 | K10: =IF(G10>0,C10/G10,"") | L10: =IFERROR(H10/E10,"") -> 0.35993394 | M10: =IFERROR(C10/H10*1000,"") -> 1.7584737 | N10: =IFERROR(C10/F10*1000,"") -> 1.2784555
A11: Unlabelled (results ≠ reach) | B11: BEFORE | C11: =SUMIFS('Data BEFORE'!$F$2:$F$48,'Data BEFORE'!$D$2:$D$48,$A11) -> 0 | D11: =C11/SUM('Data BEFORE'!$F$2:$F$48) -> 0 | E11: =SUMIFS('Data BEFORE'!$H$2:$H$48,'Data BEFORE'!$D$2:$D$48,$A11) -> 0 | F11: =SUMIFS('Data BEFORE'!$G$2:$G$48,'Data BEFORE'!$D$2:$D$48,$A11) -> 0 | G11: =SUMIFS('Data BEFORE'!$I$2:$I$48,'Data BEFORE'!$D$2:$D$48,$A11) -> 0 | H11: =SUMIFS('Data BEFORE'!$J$2:$J$48,'Data BEFORE'!$D$2:$D$48,$A11) -> 0 | I11: =IFERROR(C11/E11*1000,"") | J11: =IFERROR(G11/E11,"") | K11: =IF(G11>0,C11/G11,"") | L11: =IFERROR(H11/E11,"") | M11: =IFERROR(C11/H11*1000,"") | N11: =IFERROR(C11/F11*1000,"")
A12: Unlabelled (results ≠ reach) | B12: AFTER | C12: =SUMIFS('Data AFTER'!$F$2:$F$52,'Data AFTER'!$D$2:$D$52,$A12) -> 621.95 | D12: =C12/SUM('Data AFTER'!$F$2:$F$52) -> 0.025317491 | E12: =SUMIFS('Data AFTER'!$H$2:$H$52,'Data AFTER'!$D$2:$D$52,$A12) -> 2259715 | F12: =SUMIFS('Data AFTER'!$G$2:$G$52,'Data AFTER'!$D$2:$D$52,$A12) -> 1107096 | G12: =SUMIFS('Data AFTER'!$I$2:$I$52,'Data AFTER'!$D$2:$D$52,$A12) -> 1 | H12: =SUMIFS('Data AFTER'!$J$2:$J$52,'Data AFTER'!$D$2:$D$52,$A12) -> 776955 | I12: =IFERROR(C12/E12*1000,"") -> 0.27523382 | J12: =IFERROR(G12/E12,"") -> 4.4253368e-07 | K12: =IF(G12>0,C12/G12,"") -> 621.95 | L12: =IFERROR(H12/E12,"") -> 0.34382876 | M12: =IFERROR(C12/H12*1000,"") -> 0.80049681 | N12: =IFERROR(C12/F12*1000,"") -> 0.56178507
A13: App promotion | B13: BEFORE | C13: =SUMIFS('Data BEFORE'!$F$2:$F$48,'Data BEFORE'!$D$2:$D$48,$A13) -> 0 | D13: =C13/SUM('Data BEFORE'!$F$2:$F$48) -> 0 | E13: =SUMIFS('Data BEFORE'!$H$2:$H$48,'Data BEFORE'!$D$2:$D$48,$A13) -> 0 | F13: =SUMIFS('Data BEFORE'!$G$2:$G$48,'Data BEFORE'!$D$2:$D$48,$A13) -> 0 | G13: =SUMIFS('Data BEFORE'!$I$2:$I$48,'Data BEFORE'!$D$2:$D$48,$A13) -> 0 | H13: =SUMIFS('Data BEFORE'!$J$2:$J$48,'Data BEFORE'!$D$2:$D$48,$A13) -> 0 | I13: =IFERROR(C13/E13*1000,"") | J13: =IFERROR(G13/E13,"") | K13: =IF(G13>0,C13/G13,"") | L13: =IFERROR(H13/E13,"") | M13: =IFERROR(C13/H13*1000,"") | N13: =IFERROR(C13/F13*1000,"")
A14: App promotion | B14: AFTER | C14: =SUMIFS('Data AFTER'!$F$2:$F$52,'Data AFTER'!$D$2:$D$52,$A14) -> 5.17 | D14: =C14/SUM('Data AFTER'!$F$2:$F$52) -> 0.0002104533 | E14: =SUMIFS('Data AFTER'!$H$2:$H$52,'Data AFTER'!$D$2:$D$52,$A14) -> 20735 | F14: =SUMIFS('Data AFTER'!$G$2:$G$52,'Data AFTER'!$D$2:$D$52,$A14) -> 19540 | G14: =SUMIFS('Data AFTER'!$I$2:$I$52,'Data AFTER'!$D$2:$D$52,$A14) -> 116 | H14: =SUMIFS('Data AFTER'!$J$2:$J$52,'Data AFTER'!$D$2:$D$52,$A14) -> 7595 | I14: =IFERROR(C14/E14*1000,"") -> 0.24933687 | J14: =IFERROR(G14/E14,"") -> 0.0055944056 | K14: =IF(G14>0,C14/G14,"") -> 0.044568966 | L14: =IFERROR(H14/E14,"") -> 0.36628888 | M14: =IFERROR(C14/H14*1000,"") -> 0.68071099 | N14: =IFERROR(C14/F14*1000,"") -> 0.26458547

Sheet Like-for-like
A1: Like-for-like initiatives – Reach-objective ads only
A2: Matched only where the product keyword appears in both periods. Mixology and Happy Meal rest on one BEFORE ad each.
A4: Initiative | B4: BEFORE ads | C4: AFTER ads | D4: BEFORE spend | E4: AFTER spend | F4: BEFORE cost/1K reached | G4: AFTER cost/1K reached | H4: % change cost/1K | I4: BEFORE CPM | J4: AFTER CPM | K4: BEFORE CTR | L4: AFTER CTR | M4: % change CTR | N4: BEFORE view rate | O4: AFTER view rate | P4: % change view rate | Q4: BEFORE freq (ad level) | R4: AFTER freq (ad level)
A5: FIFA / World Cup | B5: =COUNTIFS('Data BEFORE'!$E$2:$E$48,$A5,'Data BEFORE'!$D$2:$D$48,"Reach") -> 17 | C5: =COUNTIFS('Data AFTER'!$E$2:$E$52,$A5,'Data AFTER'!$D$2:$D$52,"Reach") -> 7 | D5: =SUMIFS('Data BEFORE'!$F$2:$F$48,'Data BEFORE'!$E$2:$E$48,$A5,'Data BEFORE'!$D$2:$D$48,"Reach") -> 7001.92 | E5: =SUMIFS('Data AFTER'!$F$2:$F$52,'Data AFTER'!$E$2:$E$52,$A5,'Data AFTER'!$D$2:$D$52,"Reach") -> 3310 | F5: =D5/SUMIFS('Data BEFORE'!$G$2:$G$48,'Data BEFORE'!$E$2:$E$48,$A5,'Data BEFORE'!$D$2:$D$48,"Reach")*1000 -> 0.34305268 | G5: =E5/SUMIFS('Data AFTER'!$G$2:$G$52,'Data AFTER'!$E$2:$E$52,$A5,'Data AFTER'!$D$2:$D$52,"Reach")*1000 -> 0.33781329 | H5: =(G5-F5)/F5 -> -0.015272855 | I5: =D5/SUMIFS('Data BEFORE'!$H$2:$H$48,'Data BEFORE'!$E$2:$E$48,$A5,'Data BEFORE'!$D$2:$D$48,"Reach")*1000 -> 0.27737683 | J5: =E5/SUMIFS('Data AFTER'!$H$2:$H$52,'Data AFTER'!$E$2:$E$52,$A5,'Data AFTER'!$D$2:$D$52,"Reach")*1000 -> 0.28862978 | K5: =SUMIFS('Data BEFORE'!$I$2:$I$48,'Data BEFORE'!$E$2:$E$48,$A5,'Data BEFORE'!$D$2:$D$48,"Reach")/SUMIFS('Data BEFORE'!$H$2:$H$48,'Data BEFORE'!$E$2:$E$48,$A5,'Data BEFORE'!$D$2:$D$48,"Reach") -> 0.0021625894 | L5: =SUMIFS('Data AFTER'!$I$2:$I$52,'Data AFTER'!$E$2:$E$52,$A5,'Data AFTER'!$D$2:$D$52,"Reach")/SUMIFS('Data AFTER'!$H$2:$H$52,'Data AFTER'!$E$2:$E$52,$A5,'Data AFTER'!$D$2:$D$52,"Reach") -> 0.0022671826 | M5: =(L5-K5)/K5 -> 0.048364771 | N5: =SUMIFS('Data BEFORE'!$J$2:$J$48,'Data BEFORE'!$E$2:$E$48,$A5,'Data BEFORE'!$D$2:$D$48,"Reach")/SUMIFS('Data BEFORE'!$H$2:$H$48,'Data BEFORE'!$E$2:$E$48,$A5,'Data BEFORE'!$D$2:$D$48,"Reach") -> 0.23913804 | O5: =SUMIFS('Data AFTER'!$J$2:$J$52,'Data AFTER'!$E$2:$E$52,$A5,'Data AFTER'!$D$2:$D$52,"Reach")/SUMIFS('Data AFTER'!$H$2:$H$52,'Data AFTER'!$E$2:$E$52,$A5,'Data AFTER'!$D$2:$D$52,"Reach") -> 0.2687057 | P5: =(O5-N5)/N5 -> 0.12364263 | Q5: =SUMIFS('Data BEFORE'!$H$2:$H$48,'Data BEFORE'!$E$2:$E$48,$A5,'Data BEFORE'!$D$2:$D$48,"Reach")/SUMIFS('Data BEFORE'!$G$2:$G$48,'Data BEFORE'!$E$2:$E$48,$A5,'Data BEFORE'!$D$2:$D$48,"Reach") -> 1.2367749 | R5: =SUMIFS('Data AFTER'!$H$2:$H$52,'Data AFTER'!$E$2:$E$52,$A5,'Data AFTER'!$D$2:$D$52,"Reach")/SUMIFS('Data AFTER'!$G$2:$G$52,'Data AFTER'!$E$2:$E$52,$A5,'Data AFTER'!$D$2:$D$52,"Reach") -> 1.1704034
A6: Mixology | B6: =COUNTIFS('Data BEFORE'!$E$2:$E$48,$A6,'Data BEFORE'!$D$2:$D$48,"Reach") -> 1 | C6: =COUNTIFS('Data AFTER'!$E$2:$E$52,$A6,'Data AFTER'!$D$2:$D$52,"Reach") -> 9 | D6: =SUMIFS('Data BEFORE'!$F$2:$F$48,'Data BEFORE'!$E$2:$E$48,$A6,'Data BEFORE'!$D$2:$D$48,"Reach") -> 433.33 | E6: =SUMIFS('Data AFTER'!$F$2:$F$52,'Data AFTER'!$E$2:$E$52,$A6,'Data AFTER'!$D$2:$D$52,"Reach") -> 3846.38 | F6: =D6/SUMIFS('Data BEFORE'!$G$2:$G$48,'Data BEFORE'!$E$2:$E$48,$A6,'Data BEFORE'!$D$2:$D$48,"Reach")*1000 -> 0.42350676 | G6: =E6/SUMIFS('Data AFTER'!$G$2:$G$52,'Data AFTER'!$E$2:$E$52,$A6,'Data AFTER'!$D$2:$D$52,"Reach")*1000 -> 0.3052857 | H6: =(G6-F6)/F6 -> -0.27914799 | I6: =D6/SUMIFS('Data BEFORE'!$H$2:$H$48,'Data BEFORE'!$E$2:$E$48,$A6,'Data BEFORE'!$D$2:$D$48,"Reach")*1000 -> 0.37251217 | J6: =E6/SUMIFS('Data AFTER'!$H$2:$H$52,'Data AFTER'!$E$2:$E$52,$A6,'Data AFTER'!$D$2:$D$52,"Reach")*1000 -> 0.23217547 | K6: =SUMIFS('Data BEFORE'!$I$2:$I$48,'Data BEFORE'!$E$2:$E$48,$A6,'Data BEFORE'!$D$2:$D$48,"Reach")/SUMIFS('Data BEFORE'!$H$2:$H$48,'Data BEFORE'!$E$2:$E$48,$A6,'Data BEFORE'!$D$2:$D$48,"Reach") -> 0.0023201956 | L6: =SUMIFS('Data AFTER'!$I$2:$I$52,'Data AFTER'!$E$2:$E$52,$A6,'Data AFTER'!$D$2:$D$52,"Reach")/SUMIFS('Data AFTER'!$H$2:$H$52,'Data AFTER'!$E$2:$E$52,$A6,'Data AFTER'!$D$2:$D$52,"Reach") -> 0.0024337384 | M6: =(L6-K6)/K6 -> 0.048936759 | N6: =SUMIFS('Data BEFORE'!$J$2:$J$48,'Data BEFORE'!$E$2:$E$48,$A6,'Data BEFORE'!$D$2:$D$48,"Reach")/SUMIFS('Data BEFORE'!$H$2:$H$48,'Data BEFORE'!$E$2:$E$48,$A6,'Data BEFORE'!$D$2:$D$48,"Reach") -> 0.20297198 | O6: =SUMIFS('Data AFTER'!$J$2:$J$52,'Data AFTER'!$E$2:$E$52,$A6,'Data AFTER'!$D$2:$D$52,"Reach")/SUMIFS('Data AFTER'!$H$2:$H$52,'Data AFTER'!$E$2:$E$52,$A6,'Data AFTER'!$D$2:$D$52,"Reach") -> 0.13017854 | P6: =(O6-N6)/N6 -> -0.3586379 | Q6: =SUMIFS('Data BEFORE'!$H$2:$H$48,'Data BEFORE'!$E$2:$E$48,$A6,'Data BEFORE'!$D$2:$D$48,"Reach")/SUMIFS('Data BEFORE'!$G$2:$G$48,'Data BEFORE'!$E$2:$E$48,$A6,'Data BEFORE'!$D$2:$D$48,"Reach") -> 1.1368937 | R6: =SUMIFS('Data AFTER'!$H$2:$H$52,'Data AFTER'!$E$2:$E$52,$A6,'Data AFTER'!$D$2:$D$52,"Reach")/SUMIFS('Data AFTER'!$G$2:$G$52,'Data AFTER'!$E$2:$E$52,$A6,'Data AFTER'!$D$2:$D$52,"Reach") -> 1.3148921
A7: Grimace | B7: =COUNTIFS('Data BEFORE'!$E$2:$E$48,$A7,'Data BEFORE'!$D$2:$D$48,"Reach") -> 2 | C7: =COUNTIFS('Data AFTER'!$E$2:$E$52,$A7,'Data AFTER'!$D$2:$D$52,"Reach") -> 2 | D7: =SUMIFS('Data BEFORE'!$F$2:$F$48,'Data BEFORE'!$E$2:$E$48,$A7,'Data BEFORE'!$D$2:$D$48,"Reach") -> 970.04 | E7: =SUMIFS('Data AFTER'!$F$2:$F$52,'Data AFTER'!$E$2:$E$52,$A7,'Data AFTER'!$D$2:$D$52,"Reach") -> 756.63 | F7: =D7/SUMIFS('Data BEFORE'!$G$2:$G$48,'Data BEFORE'!$E$2:$E$48,$A7,'Data BEFORE'!$D$2:$D$48,"Reach")*1000 -> 0.30898721 | G7: =E7/SUMIFS('Data AFTER'!$G$2:$G$52,'Data AFTER'!$E$2:$E$52,$A7,'Data AFTER'!$D$2:$D$52,"Reach")*1000 -> 0.22517818 | H7: =(G7-F7)/F7 -> -0.27123784 | I7: =D7/SUMIFS('Data BEFORE'!$H$2:$H$48,'Data BEFORE'!$E$2:$E$48,$A7,'Data BEFORE'!$D$2:$D$48,"Reach")*1000 -> 0.17417907 | J7: =E7/SUMIFS('Data AFTER'!$H$2:$H$52,'Data AFTER'!$E$2:$E$52,$A7,'Data AFTER'!$D$2:$D$52,"Reach")*1000 -> 0.21260006 | K7: =SUMIFS('Data BEFORE'!$I$2:$I$48,'Data BEFORE'!$E$2:$E$48,$A7,'Data BEFORE'!$D$2:$D$48,"Reach")/SUMIFS('Data BEFORE'!$H$2:$H$48,'Data BEFORE'!$E$2:$E$48,$A7,'Data BEFORE'!$D$2:$D$48,"Reach") -> 0.0019252278 | L7: =SUMIFS('Data AFTER'!$I$2:$I$52,'Data AFTER'!$E$2:$E$52,$A7,'Data AFTER'!$D$2:$D$52,"Reach")/SUMIFS('Data AFTER'!$H$2:$H$52,'Data AFTER'!$E$2:$E$52,$A7,'Data AFTER'!$D$2:$D$52,"Reach") -> 0.0021208586 | M7: =(L7-K7)/K7 -> 0.10161435 | N7: =SUMIFS('Data BEFORE'!$J$2:$J$48,'Data BEFORE'!$E$2:$E$48,$A7,'Data BEFORE'!$D$2:$D$48,"Reach")/SUMIFS('Data BEFORE'!$H$2:$H$48,'Data BEFORE'!$E$2:$E$48,$A7,'Data BEFORE'!$D$2:$D$48,"Reach") -> 0.27448484 | O7: =SUMIFS('Data AFTER'!$J$2:$J$52,'Data AFTER'!$E$2:$E$52,$A7,'Data AFTER'!$D$2:$D$52,"Reach")/SUMIFS('Data AFTER'!$H$2:$H$52,'Data AFTER'!$E$2:$E$52,$A7,'Data AFTER'!$D$2:$D$52,"Reach") -> 0.14680202 | P7: =(O7-N7)/N7 -> -0.46517257 | Q7: =SUMIFS('Data BEFORE'!$H$2:$H$48,'Data BEFORE'!$E$2:$E$48,$A7,'Data BEFORE'!$D$2:$D$48,"Reach")/SUMIFS('Data BEFORE'!$G$2:$G$48,'Data BEFORE'!$E$2:$E$48,$A7,'Data BEFORE'!$D$2:$D$48,"Reach") -> 1.7739629 | R7: =SUMIFS('Data AFTER'!$H$2:$H$52,'Data AFTER'!$E$2:$E$52,$A7,'Data AFTER'!$D$2:$D$52,"Reach")/SUMIFS('Data AFTER'!$G$2:$G$52,'Data AFTER'!$E$2:$E$52,$A7,'Data AFTER'!$D$2:$D$52,"Reach") -> 1.0591633
A8: Happy Meal | B8: =COUNTIFS('Data BEFORE'!$E$2:$E$48,$A8,'Data BEFORE'!$D$2:$D$48,"Reach") -> 1 | C8: =COUNTIFS('Data AFTER'!$E$2:$E$52,$A8,'Data AFTER'!$D$2:$D$52,"Reach") -> 12 | D8: =SUMIFS('Data BEFORE'!$F$2:$F$48,'Data BEFORE'!$E$2:$E$48,$A8,'Data BEFORE'!$D$2:$D$48,"Reach") -> 621.47 | E8: =SUMIFS('Data AFTER'!$F$2:$F$52,'Data AFTER'!$E$2:$E$52,$A8,'Data AFTER'!$D$2:$D$52,"Reach") -> 3571.04 | F8: =D8/SUMIFS('Data BEFORE'!$G$2:$G$48,'Data BEFORE'!$E$2:$E$48,$A8,'Data BEFORE'!$D$2:$D$48,"Reach")*1000 -> 0.33983118 | G8: =E8/SUMIFS('Data AFTER'!$G$2:$G$52,'Data AFTER'!$E$2:$E$52,$A8,'Data AFTER'!$D$2:$D$52,"Reach")*1000 -> 0.37025413 | H8: =(G8-F8)/F8 -> 0.089523733 | I8: =D8/SUMIFS('Data BEFORE'!$H$2:$H$48,'Data BEFORE'!$E$2:$E$48,$A8,'Data BEFORE'!$D$2:$D$48,"Reach")*1000 -> 0.19856927 | J8: =E8/SUMIFS('Data AFTER'!$H$2:$H$52,'Data AFTER'!$E$2:$E$52,$A8,'Data AFTER'!$D$2:$D$52,"Reach")*1000 -> 0.2658946 | K8: =SUMIFS('Data BEFORE'!$I$2:$I$48,'Data BEFORE'!$E$2:$E$48,$A8,'Data BEFORE'!$D$2:$D$48,"Reach")/SUMIFS('Data BEFORE'!$H$2:$H$48,'Data BEFORE'!$E$2:$E$48,$A8,'Data BEFORE'!$D$2:$D$48,"Reach") -> 0.0025877557 | L8: =SUMIFS('Data AFTER'!$I$2:$I$52,'Data AFTER'!$E$2:$E$52,$A8,'Data AFTER'!$D$2:$D$52,"Reach")/SUMIFS('Data AFTER'!$H$2:$H$52,'Data AFTER'!$E$2:$E$52,$A8,'Data AFTER'!$D$2:$D$52,"Reach") -> 0.0024420928 | M8: =(L8-K8)/K8 -> -0.056289281 | N8: =SUMIFS('Data BEFORE'!$J$2:$J$48,'Data BEFORE'!$E$2:$E$48,$A8,'Data BEFORE'!$D$2:$D$48,"Reach")/SUMIFS('Data BEFORE'!$H$2:$H$48,'Data BEFORE'!$E$2:$E$48,$A8,'Data BEFORE'!$D$2:$D$48,"Reach") -> 0.1652502 | O8: =SUMIFS('Data AFTER'!$J$2:$J$52,'Data AFTER'!$E$2:$E$52,$A8,'Data AFTER'!$D$2:$D$52,"Reach")/SUMIFS('Data AFTER'!$H$2:$H$52,'Data AFTER'!$E$2:$E$52,$A8,'Data AFTER'!$D$2:$D$52,"Reach") -> 0.14627092 | P8: =(O8-N8)/N8 -> -0.11485179 | Q8: =SUMIFS('Data BEFORE'!$H$2:$H$48,'Data BEFORE'!$E$2:$E$48,$A8,'Data BEFORE'!$D$2:$D$48,"Reach")/SUMIFS('Data BEFORE'!$G$2:$G$48,'Data BEFORE'!$E$2:$E$48,$A8,'Data BEFORE'!$D$2:$D$48,"Reach") -> 1.7113986 | R8: =SUMIFS('Data AFTER'!$H$2:$H$52,'Data AFTER'!$E$2:$E$52,$A8,'Data AFTER'!$D$2:$D$52,"Reach")/SUMIFS('Data AFTER'!$G$2:$G$52,'Data AFTER'!$E$2:$E$52,$A8,'Data AFTER'!$D$2:$D$52,"Reach") -> 1.3924846
A9: Chicken | B9: =COUNTIFS('Data BEFORE'!$E$2:$E$48,$A9,'Data BEFORE'!$D$2:$D$48,"Reach") -> 3 | C9: =COUNTIFS('Data AFTER'!$E$2:$E$52,$A9,'Data AFTER'!$D$2:$D$52,"Reach") -> 4 | D9: =SUMIFS('Data BEFORE'!$F$2:$F$48,'Data BEFORE'!$E$2:$E$48,$A9,'Data BEFORE'!$D$2:$D$48,"Reach") -> 2364.25 | E9: =SUMIFS('Data AFTER'!$F$2:$F$52,'Data AFTER'!$E$2:$E$52,$A9,'Data AFTER'!$D$2:$D$52,"Reach") -> 5510.01 | F9: =D9/SUMIFS('Data BEFORE'!$G$2:$G$48,'Data BEFORE'!$E$2:$E$48,$A9,'Data BEFORE'!$D$2:$D$48,"Reach")*1000 -> 0.38757034 | G9: =E9/SUMIFS('Data AFTER'!$G$2:$G$52,'Data AFTER'!$E$2:$E$52,$A9,'Data AFTER'!$D$2:$D$52,"Reach")*1000 -> 0.65594217 | H9: =(G9-F9)/F9 -> 0.69244677 | I9: =D9/SUMIFS('Data BEFORE'!$H$2:$H$48,'Data BEFORE'!$E$2:$E$48,$A9,'Data BEFORE'!$D$2:$D$48,"Reach")*1000 -> 0.24660333 | J9: =E9/SUMIFS('Data AFTER'!$H$2:$H$52,'Data AFTER'!$E$2:$E$52,$A9,'Data AFTER'!$D$2:$D$52,"Reach")*1000 -> 0.29211329 | K9: =SUMIFS('Data BEFORE'!$I$2:$I$48,'Data BEFORE'!$E$2:$E$48,$A9,'Data BEFORE'!$D$2:$D$48,"Reach")/SUMIFS('Data BEFORE'!$H$2:$H$48,'Data BEFORE'!$E$2:$E$48,$A9,'Data BEFORE'!$D$2:$D$48,"Reach") -> 0.0023371644 | L9: =SUMIFS('Data AFTER'!$I$2:$I$52,'Data AFTER'!$E$2:$E$52,$A9,'Data AFTER'!$D$2:$D$52,"Reach")/SUMIFS('Data AFTER'!$H$2:$H$52,'Data AFTER'!$E$2:$E$52,$A9,'Data AFTER'!$D$2:$D$52,"Reach") -> 0.0024830645 | M9: =(L9-K9)/K9 -> 0.062426131 | N9: =SUMIFS('Data BEFORE'!$J$2:$J$48,'Data BEFORE'!$E$2:$E$48,$A9,'Data BEFORE'!$D$2:$D$48,"Reach")/SUMIFS('Data BEFORE'!$H$2:$H$48,'Data BEFORE'!$E$2:$E$48,$A9,'Data BEFORE'!$D$2:$D$48,"Reach") -> 0.16667371 | O9: =SUMIFS('Data AFTER'!$J$2:$J$52,'Data AFTER'!$E$2:$E$52,$A9,'Data AFTER'!$D$2:$D$52,"Reach")/SUMIFS('Data AFTER'!$H$2:$H$52,'Data AFTER'!$E$2:$E$52,$A9,'Data AFTER'!$D$2:$D$52,"Reach") -> 0.18450717 | P9: =(O9-N9)/N9 -> 0.10699623 | Q9: =SUMIFS('Data BEFORE'!$H$2:$H$48,'Data BEFORE'!$E$2:$E$48,$A9,'Data BEFORE'!$D$2:$D$48,"Reach")/SUMIFS('Data BEFORE'!$G$2:$G$48,'Data BEFORE'!$E$2:$E$48,$A9,'Data BEFORE'!$D$2:$D$48,"Reach") -> 1.5716347 | R9: =SUMIFS('Data AFTER'!$H$2:$H$52,'Data AFTER'!$E$2:$E$52,$A9,'Data AFTER'!$D$2:$D$52,"Reach")/SUMIFS('Data AFTER'!$G$2:$G$52,'Data AFTER'!$E$2:$E$52,$A9,'Data AFTER'!$D$2:$D$52,"Reach") -> 2.2455061
A10: McCafé | B10: =COUNTIFS('Data BEFORE'!$E$2:$E$48,$A10,'Data BEFORE'!$D$2:$D$48,"Reach") -> 2 | C10: =COUNTIFS('Data AFTER'!$E$2:$E$52,$A10,'Data AFTER'!$D$2:$D$52,"Reach") -> 2 | D10: =SUMIFS('Data BEFORE'!$F$2:$F$48,'Data BEFORE'!$E$2:$E$48,$A10,'Data BEFORE'!$D$2:$D$48,"Reach") -> 682.35 | E10: =SUMIFS('Data AFTER'!$F$2:$F$52,'Data AFTER'!$E$2:$E$52,$A10,'Data AFTER'!$D$2:$D$52,"Reach") -> 2730.67 | F10: =D10/SUMIFS('Data BEFORE'!$G$2:$G$48,'Data BEFORE'!$E$2:$E$48,$A10,'Data BEFORE'!$D$2:$D$48,"Reach")*1000 -> 0.24836046 | G10: =E10/SUMIFS('Data AFTER'!$G$2:$G$52,'Data AFTER'!$E$2:$E$52,$A10,'Data AFTER'!$D$2:$D$52,"Reach")*1000 -> 0.63032369 | H10: =(G10-F10)/F10 -> 1.537939 | I10: =D10/SUMIFS('Data BEFORE'!$H$2:$H$48,'Data BEFORE'!$E$2:$E$48,$A10,'Data BEFORE'!$D$2:$D$48,"Reach")*1000 -> 0.21994773 | J10: =E10/SUMIFS('Data AFTER'!$H$2:$H$52,'Data AFTER'!$E$2:$E$52,$A10,'Data AFTER'!$D$2:$D$52,"Reach")*1000 -> 0.23407197 | K10: =SUMIFS('Data BEFORE'!$I$2:$I$48,'Data BEFORE'!$E$2:$E$48,$A10,'Data BEFORE'!$D$2:$D$48,"Reach")/SUMIFS('Data BEFORE'!$H$2:$H$48,'Data BEFORE'!$E$2:$E$48,$A10,'Data BEFORE'!$D$2:$D$48,"Reach") -> 0.0024520296 | L10: =SUMIFS('Data AFTER'!$I$2:$I$52,'Data AFTER'!$E$2:$E$52,$A10,'Data AFTER'!$D$2:$D$52,"Reach")/SUMIFS('Data AFTER'!$H$2:$H$52,'Data AFTER'!$E$2:$E$52,$A10,'Data AFTER'!$D$2:$D$52,"Reach") -> 0.0023226586 | M10: =(L10-K10)/K10 -> -0.05276079 | N10: =SUMIFS('Data BEFORE'!$J$2:$J$48,'Data BEFORE'!$E$2:$E$48,$A10,'Data BEFORE'!$D$2:$D$48,"Reach")/SUMIFS('Data BEFORE'!$H$2:$H$48,'Data BEFORE'!$E$2:$E$48,$A10,'Data BEFORE'!$D$2:$D$48,"Reach") -> 0.31648008 | O10: =SUMIFS('Data AFTER'!$J$2:$J$52,'Data AFTER'!$E$2:$E$52,$A10,'Data AFTER'!$D$2:$D$52,"Reach")/SUMIFS('Data AFTER'!$H$2:$H$52,'Data AFTER'!$E$2:$E$52,$A10,'Data AFTER'!$D$2:$D$52,"Reach") -> 0.069159267 | P10: =(O10-N10)/N10 -> -0.78147355 | Q10: =SUMIFS('Data BEFORE'!$H$2:$H$48,'Data BEFORE'!$E$2:$E$48,$A10,'Data BEFORE'!$D$2:$D$48,"Reach")/SUMIFS('Data BEFORE'!$G$2:$G$48,'Data BEFORE'!$E$2:$E$48,$A10,'Data BEFORE'!$D$2:$D$48,"Reach") -> 1.1291795 | R10: =SUMIFS('Data AFTER'!$H$2:$H$52,'Data AFTER'!$E$2:$E$52,$A10,'Data AFTER'!$D$2:$D$52,"Reach")/SUMIFS('Data AFTER'!$G$2:$G$52,'Data AFTER'!$E$2:$E$52,$A10,'Data AFTER'!$D$2:$D$52,"Reach") -> 2.6928628

Sheet Campaigns BEFORE
A1: Campaigns BEFORE
A2: SUMIFS over the ad-level data; rates recalculated from totals. Sorted by spend.
A4: Campaign | B4: Objective | C4: Ads | D4: Spend (USD) | E4: Share of spend | F4: Reach (ad level) | G4: Impressions | H4: Clicks | I4: 2-sec views | J4: Frequency (ad level) | K4: CPM (USD) | L4: CTR | M4: CPC (USD) | N4: 2-sec view rate | O4: Cost / 1K 2-sec views (USD) | P4: Cost / 1K reached (USD)
A5: Reach_June'26 | B5: Reach | C5: =COUNTIFS('Data BEFORE'!$A$2:$A$48,$A5) -> 24 | D5: =SUMIFS('Data BEFORE'!$F$2:$F$48,'Data BEFORE'!$A$2:$A$48,$A5) -> 10996.83 | E5: =D5/SUM('Data BEFORE'!$F$2:$F$48) -> 0.40346619 | F5: =SUMIFS('Data BEFORE'!$G$2:$G$48,'Data BEFORE'!$A$2:$A$48,$A5) -> 29728200 | G5: =SUMIFS('Data BEFORE'!$H$2:$H$48,'Data BEFORE'!$A$2:$A$48,$A5) -> 39701659 | H5: =SUMIFS('Data BEFORE'!$I$2:$I$48,'Data BEFORE'!$A$2:$A$48,$A5) -> 90529 | I5: =SUMIFS('Data BEFORE'!$J$2:$J$48,'Data BEFORE'!$A$2:$A$48,$A5) -> 9127912 | J5: =IFERROR(G5/F5,"") -> 1.3354882 | K5: =IFERROR(D5/G5*1000,"") -> 0.27698666 | L5: =IFERROR(H5/G5,"") -> 0.0022802322 | M5: =IF(H5>0,D5/H5,"") -> 0.12147301 | N5: =IFERROR(I5/G5,"") -> 0.22991261 | O5: =IFERROR(D5/I5*1000,"") -> 1.2047476 | P5: =IFERROR(D5/F5*1000,"") -> 0.36991241
A6: Reach_April'26 | B6: Reach | C6: =COUNTIFS('Data BEFORE'!$A$2:$A$48,$A6) -> 9 | D6: =SUMIFS('Data BEFORE'!$F$2:$F$48,'Data BEFORE'!$A$2:$A$48,$A6) -> 7000 | E6: =D6/SUM('Data BEFORE'!$F$2:$F$48) -> 0.25682522 | F6: =SUMIFS('Data BEFORE'!$G$2:$G$48,'Data BEFORE'!$A$2:$A$48,$A6) -> 14965894 | G6: =SUMIFS('Data BEFORE'!$H$2:$H$48,'Data BEFORE'!$A$2:$A$48,$A6) -> 26217754 | H6: =SUMIFS('Data BEFORE'!$I$2:$I$48,'Data BEFORE'!$A$2:$A$48,$A6) -> 74336 | I6: =SUMIFS('Data BEFORE'!$J$2:$J$48,'Data BEFORE'!$A$2:$A$48,$A6) -> 7168839 | J6: =IFERROR(G6/F6,"") -> 1.7518335 | K6: =IFERROR(D6/G6*1000,"") -> 0.26699465 | L6: =IFERROR(H6/G6,"") -> 0.0028353306 | M6: =IF(H6>0,D6/H6,"") -> 0.094167025 | N6: =IFERROR(I6/G6,"") -> 0.27343452 | O6: =IFERROR(D6/I6*1000,"") -> 0.97644821 | P6: =IFERROR(D6/F6*1000,"") -> 0.46773016
A7: Reach_May'26 | B7: Reach | C7: =COUNTIFS('Data BEFORE'!$A$2:$A$48,$A7) -> 8 | D7: =SUMIFS('Data BEFORE'!$F$2:$F$48,'Data BEFORE'!$A$2:$A$48,$A7) -> 7000 | E7: =D7/SUM('Data BEFORE'!$F$2:$F$48) -> 0.25682522 | F7: =SUMIFS('Data BEFORE'!$G$2:$G$48,'Data BEFORE'!$A$2:$A$48,$A7) -> 19665770 | G7: =SUMIFS('Data BEFORE'!$H$2:$H$48,'Data BEFORE'!$A$2:$A$48,$A7) -> 35530416 | H7: =SUMIFS('Data BEFORE'!$I$2:$I$48,'Data BEFORE'!$A$2:$A$48,$A7) -> 81684 | I7: =SUMIFS('Data BEFORE'!$J$2:$J$48,'Data BEFORE'!$A$2:$A$48,$A7) -> 6938421 | J7: =IFERROR(G7/F7,"") -> 1.8067137 | K7: =IFERROR(D7/G7*1000,"") -> 0.1970143 | L7: =IFERROR(H7/G7,"") -> 0.002298988 | M7: =IF(H7>0,D7/H7,"") -> 0.085696097 | N7: =IFERROR(I7/G7,"") -> 0.19528116 | O7: =IFERROR(D7/I7*1000,"") -> 1.0088751 | P7: =IFERROR(D7/F7*1000,"") -> 0.35594843
A8: Community interaction_May'26 | B8: Community interaction | C8: =COUNTIFS('Data BEFORE'!$A$2:$A$48,$A8) -> 2 | D8: =SUMIFS('Data BEFORE'!$F$2:$F$48,'Data BEFORE'!$A$2:$A$48,$A8) -> 1414.83 | E8: =D8/SUM('Data BEFORE'!$F$2:$F$48) -> 0.051909147 | F8: =SUMIFS('Data BEFORE'!$G$2:$G$48,'Data BEFORE'!$A$2:$A$48,$A8) -> 1011718 | G8: =SUMIFS('Data BEFORE'!$H$2:$H$48,'Data BEFORE'!$A$2:$A$48,$A8) -> 2906700 | H8: =SUMIFS('Data BEFORE'!$I$2:$I$48,'Data BEFORE'!$A$2:$A$48,$A8) -> 0 | I8: =SUMIFS('Data BEFORE'!$J$2:$J$48,'Data BEFORE'!$A$2:$A$48,$A8) -> 560362 | J8: =IFERROR(G8/F8,"") -> 2.8730338 | K8: =IFERROR(D8/G8*1000,"") -> 0.48674786 | L8: =IFERROR(H8/G8,"") -> 0 | M8: =IF(H8>0,D8/H8,"") | N8: =IFERROR(I8/G8,"") -> 0.19278288 | O8: =IFERROR(D8/I8*1000,"") -> 2.52485 | P8: =IFERROR(D8/F8*1000,"") -> 1.398443
A9: Взаимодействие с сообществом20260611150844 | B9: Community interaction | C9: =COUNTIFS('Data BEFORE'!$A$2:$A$48,$A9) -> 3 | D9: =SUMIFS('Data BEFORE'!$F$2:$F$48,'Data BEFORE'!$A$2:$A$48,$A9) -> 576.67 | E9: =D9/SUM('Data BEFORE'!$F$2:$F$48) -> 0.021157629 | F9: =SUMIFS('Data BEFORE'!$G$2:$G$48,'Data BEFORE'!$A$2:$A$48,$A9) -> 457234 | G9: =SUMIFS('Data BEFORE'!$H$2:$H$48,'Data BEFORE'!$A$2:$A$48,$A9) -> 741947 | H9: =SUMIFS('Data BEFORE'!$I$2:$I$48,'Data BEFORE'!$A$2:$A$48,$A9) -> 0 | I9: =SUMIFS('Data BEFORE'!$J$2:$J$48,'Data BEFORE'!$A$2:$A$48,$A9) -> 281859 | J9: =IFERROR(G9/F9,"") -> 1.6226855 | K9: =IFERROR(D9/G9*1000,"") -> 0.77723881 | L9: =IFERROR(H9/G9,"") -> 0 | M9: =IF(H9>0,D9/H9,"") | N9: =IFERROR(I9/G9,"") -> 0.37989102 | O9: =IFERROR(D9/I9*1000,"") -> 2.0459521 | P9: =IFERROR(D9/F9*1000,"") -> 1.2612142
A10: Community_int_generic_22.04 | B10: Community interaction | C10: =COUNTIFS('Data BEFORE'!$A$2:$A$48,$A10) -> 1 | D10: =SUMIFS('Data BEFORE'!$F$2:$F$48,'Data BEFORE'!$A$2:$A$48,$A10) -> 267.56 | E10: =D10/SUM('Data BEFORE'!$F$2:$F$48) -> 0.0098165938 | F10: =SUMIFS('Data BEFORE'!$G$2:$G$48,'Data BEFORE'!$A$2:$A$48,$A10) -> 146099 | G10: =SUMIFS('Data BEFORE'!$H$2:$H$48,'Data BEFORE'!$A$2:$A$48,$A10) -> 258263 | H10: =SUMIFS('Data BEFORE'!$I$2:$I$48,'Data BEFORE'!$A$2:$A$48,$A10) -> 0 | I10: =SUMIFS('Data BEFORE'!$J$2:$J$48,'Data BEFORE'!$A$2:$A$48,$A10) -> 66068 | J10: =IFERROR(G10/F10,"") -> 1.767726 | K10: =IFERROR(D10/G10*1000,"") -> 1.0359982 | L10: =IFERROR(H10/G10,"") -> 0 | M10: =IF(H10>0,D10/H10,"") | N10: =IFERROR(I10/G10,"") -> 0.25581674 | O10: =IFERROR(D10/I10*1000,"") -> 4.0497669 | P10: =IFERROR(D10/F10*1000,"") -> 1.8313609
A11: Total | C11: =SUM(C5:C10) -> 47 | D11: =SUM(D5:D10) -> 27255.89 | F11: =SUM(F5:F10) -> 65974915 | G11: =SUM(G5:G10) -> 105356739 | H11: =SUM(H5:H10) -> 246549 | I11: =SUM(I5:I10) -> 24143461

Sheet Campaigns AFTER
A1: Campaigns AFTER
A2: SUMIFS over the ad-level data; rates recalculated from totals. Sorted by spend.
A4: Campaign | B4: Objective | C4: Ads | D4: Spend (USD) | E4: Share of spend | F4: Reach (ad level) | G4: Impressions | H4: Clicks | I4: 2-sec views | J4: Frequency (ad level) | K4: CPM (USD) | L4: CTR | M4: CPC (USD) | N4: 2-sec view rate | O4: Cost / 1K 2-sec views (USD) | P4: Cost / 1K reached (USD)
A5: MCchicken_Reach_July'26 | B5: Reach | C5: =COUNTIFS('Data AFTER'!$A$2:$A$52,$A5) -> 1 | D5: =SUMIFS('Data AFTER'!$F$2:$F$52,'Data AFTER'!$A$2:$A$52,$A5) -> 3594.01 | E5: =D5/SUM('Data AFTER'!$F$2:$F$52) -> 0.14630005 | F5: =SUMIFS('Data AFTER'!$G$2:$G$52,'Data AFTER'!$A$2:$A$52,$A5) -> 3359491 | G5: =SUMIFS('Data AFTER'!$H$2:$H$52,'Data AFTER'!$A$2:$A$52,$A5) -> 11212822 | H5: =SUMIFS('Data AFTER'!$I$2:$I$52,'Data AFTER'!$A$2:$A$52,$A5) -> 26184 | I5: =SUMIFS('Data AFTER'!$J$2:$J$52,'Data AFTER'!$A$2:$A$52,$A5) -> 799143 | J5: =IFERROR(G5/F5,"") -> 3.337655 | K5: =IFERROR(D5/G5*1000,"") -> 0.3205268 | L5: =IFERROR(H5/G5,"") -> 0.0023351838 | M5: =IF(H5>0,D5/H5,"") -> 0.13725978 | N5: =IFERROR(I5/G5,"") -> 0.071270462 | O5: =IFERROR(D5/I5*1000,"") -> 4.4973303 | P5: =IFERROR(D5/F5*1000,"") -> 1.0698079
A6: FIFA_Reach_July'26 | B6: Reach | C6: =COUNTIFS('Data AFTER'!$A$2:$A$52,$A6) -> 7 | D6: =SUMIFS('Data AFTER'!$F$2:$F$52,'Data AFTER'!$A$2:$A$52,$A6) -> 3310 | E6: =D6/SUM('Data AFTER'!$F$2:$F$52) -> 0.13473896 | F6: =SUMIFS('Data AFTER'!$G$2:$G$52,'Data AFTER'!$A$2:$A$52,$A6) -> 9798312 | G6: =SUMIFS('Data AFTER'!$H$2:$H$52,'Data AFTER'!$A$2:$A$52,$A6) -> 11467978 | H6: =SUMIFS('Data AFTER'!$I$2:$I$52,'Data AFTER'!$A$2:$A$52,$A6) -> 26000 | I6: =SUMIFS('Data AFTER'!$J$2:$J$52,'Data AFTER'!$A$2:$A$52,$A6) -> 3081511 | J6: =IFERROR(G6/F6,"") -> 1.1704034 | K6: =IFERROR(D6/G6*1000,"") -> 0.28862978 | L6: =IFERROR(H6/G6,"") -> 0.0022671826 | M6: =IF(H6>0,D6/H6,"") -> 0.12730769 | N6: =IFERROR(I6/G6,"") -> 0.2687057 | O6: =IFERROR(D6/I6*1000,"") -> 1.0741484 | P6: =IFERROR(D6/F6*1000,"") -> 0.33781329
A7: McCafe_Reach_Sep_26 | B7: Reach | C7: =COUNTIFS('Data AFTER'!$A$2:$A$52,$A7) -> 2 | D7: =SUMIFS('Data AFTER'!$F$2:$F$52,'Data AFTER'!$A$2:$A$52,$A7) -> 2730.67 | E7: =D7/SUM('Data AFTER'!$F$2:$F$52) -> 0.11115639 | F7: =SUMIFS('Data AFTER'!$G$2:$G$52,'Data AFTER'!$A$2:$A$52,$A7) -> 4332171 | G7: =SUMIFS('Data AFTER'!$H$2:$H$52,'Data AFTER'!$A$2:$A$52,$A7) -> 11665942 | H7: =SUMIFS('Data AFTER'!$I$2:$I$52,'Data AFTER'!$A$2:$A$52,$A7) -> 27096 | I7: =SUMIFS('Data AFTER'!$J$2:$J$52,'Data AFTER'!$A$2:$A$52,$A7) -> 806808 | J7: =IFERROR(G7/F7,"") -> 2.6928628 | K7: =IFERROR(D7/G7*1000,"") -> 0.23407197 | L7: =IFERROR(H7/G7,"") -> 0.0023226586 | M7: =IF(H7>0,D7/H7,"") -> 0.10077761 | N7: =IFERROR(I7/G7,"") -> 0.069159267 | O7: =IFERROR(D7/I7*1000,"") -> 3.3845351 | P7: =IFERROR(D7/F7*1000,"") -> 0.63032369
A8: Mixology_Reach_July'26 | B8: Reach | C8: =COUNTIFS('Data AFTER'!$A$2:$A$52,$A8) -> 6 | D8: =SUMIFS('Data AFTER'!$F$2:$F$52,'Data AFTER'!$A$2:$A$52,$A8) -> 2339 | E8: =D8/SUM('Data AFTER'!$F$2:$F$52) -> 0.095212818 | F8: =SUMIFS('Data AFTER'!$G$2:$G$52,'Data AFTER'!$A$2:$A$52,$A8) -> 8477218 | G8: =SUMIFS('Data AFTER'!$H$2:$H$52,'Data AFTER'!$A$2:$A$52,$A8) -> 9454513 | H8: =SUMIFS('Data AFTER'!$I$2:$I$52,'Data AFTER'!$A$2:$A$52,$A8) -> 23069 | I8: =SUMIFS('Data AFTER'!$J$2:$J$52,'Data AFTER'!$A$2:$A$52,$A8) -> 1384300 | J8: =IFERROR(G8/F8,"") -> 1.1152849 | K8: =IFERROR(D8/G8*1000,"") -> 0.24739508 | L8: =IFERROR(H8/G8,"") -> 0.0024399988 | M8: =IF(H8>0,D8/H8,"") -> 0.10139148 | N8: =IFERROR(I8/G8,"") -> 0.14641685 | O8: =IFERROR(D8/I8*1000,"") -> 1.6896626 | P8: =IFERROR(D8/F8*1000,"") -> 0.27591599
A9: HM_Reach_Sep'26 | B9: Reach | C9: =COUNTIFS('Data AFTER'!$A$2:$A$52,$A9) -> 3 | D9: =SUMIFS('Data AFTER'!$F$2:$F$52,'Data AFTER'!$A$2:$A$52,$A9) -> 1792.55 | E9: =D9/SUM('Data AFTER'!$F$2:$F$52) -> 0.072968678 | F9: =SUMIFS('Data AFTER'!$G$2:$G$52,'Data AFTER'!$A$2:$A$52,$A9) -> 3067126 | G9: =SUMIFS('Data AFTER'!$H$2:$H$52,'Data AFTER'!$A$2:$A$52,$A9) -> 4565246 | H9: =SUMIFS('Data AFTER'!$I$2:$I$52,'Data AFTER'!$A$2:$A$52,$A9) -> 14081 | I9: =SUMIFS('Data AFTER'!$J$2:$J$52,'Data AFTER'!$A$2:$A$52,$A9) -> 619524 | J9: =IFERROR(G9/F9,"") -> 1.4884442 | K9: =IFERROR(D9/G9*1000,"") -> 0.39265135 | L9: =IFERROR(H9/G9,"") -> 0.0030843902 | M9: =IF(H9>0,D9/H9,"") -> 0.12730275 | N9: =IFERROR(I9/G9,"") -> 0.13570441 | O9: =IFERROR(D9/I9*1000,"") -> 2.8934311 | P9: =IFERROR(D9/F9*1000,"") -> 0.58443964
A10: MCD&Spiderman_HM_Reach_Aug_26 | B10: Reach | C10: =COUNTIFS('Data AFTER'!$A$2:$A$52,$A10) -> 9 | D10: =SUMIFS('Data AFTER'!$F$2:$F$52,'Data AFTER'!$A$2:$A$52,$A10) -> 1778.49 | E10: =D10/SUM('Data AFTER'!$F$2:$F$52) -> 0.072396343 | F10: =SUMIFS('Data AFTER'!$G$2:$G$52,'Data AFTER'!$A$2:$A$52,$A10) -> 6577709 | G10: =SUMIFS('Data AFTER'!$H$2:$H$52,'Data AFTER'!$A$2:$A$52,$A10) -> 8865038 | H10: =SUMIFS('Data AFTER'!$I$2:$I$52,'Data AFTER'!$A$2:$A$52,$A10) -> 18717 | I10: =SUMIFS('Data AFTER'!$J$2:$J$52,'Data AFTER'!$A$2:$A$52,$A10) -> 1344936 | J10: =IFERROR(G10/F10,"") -> 1.3477395 | K10: =IFERROR(D10/G10*1000,"") -> 0.20061843 | L10: =IFERROR(H10/G10,"") -> 0.0021113277 | M10: =IF(H10>0,D10/H10,"") -> 0.095020035 | N10: =IFERROR(I10/G10,"") -> 0.15171238 | O10: =IFERROR(D10/I10*1000,"") -> 1.3223603 | P10: =IFERROR(D10/F10*1000,"") -> 0.27038137
A11: Mixology_Reach_Aug'26 | B11: Reach | C11: =COUNTIFS('Data AFTER'!$A$2:$A$52,$A11) -> 3 | D11: =SUMIFS('Data AFTER'!$F$2:$F$52,'Data AFTER'!$A$2:$A$52,$A11) -> 1507.38 | E11: =D11/SUM('Data AFTER'!$F$2:$F$52) -> 0.061360367 | F11: =SUMIFS('Data AFTER'!$G$2:$G$52,'Data AFTER'!$A$2:$A$52,$A11) -> 4122062 | G11: =SUMIFS('Data AFTER'!$H$2:$H$52,'Data AFTER'!$A$2:$A$52,$A11) -> 7112181 | H11: =SUMIFS('Data AFTER'!$I$2:$I$52,'Data AFTER'!$A$2:$A$52,$A11) -> 17250 | I11: =SUMIFS('Data AFTER'!$J$2:$J$52,'Data AFTER'!$A$2:$A$52,$A11) -> 772328 | J11: =IFERROR(G11/F11,"") -> 1.725394 | K11: =IFERROR(D11/G11*1000,"") -> 0.21194342 | L11: =IFERROR(H11/G11,"") -> 0.0024254163 | M11: =IF(H11>0,D11/H11,"") -> 0.087384348 | N11: =IFERROR(I11/G11,"") -> 0.10859229 | O11: =IFERROR(D11/I11*1000,"") -> 1.9517355 | P11: =IFERROR(D11/F11*1000,"") -> 0.36568591
A12: MCD&SpidermanGenZ_Reach_Aug_26 | B12: Reach | C12: =COUNTIFS('Data AFTER'!$A$2:$A$52,$A12) -> 5 | D12: =SUMIFS('Data AFTER'!$F$2:$F$52,'Data AFTER'!$A$2:$A$52,$A12) -> 1500 | E12: =D12/SUM('Data AFTER'!$F$2:$F$52) -> 0.061059952 | F12: =SUMIFS('Data AFTER'!$G$2:$G$52,'Data AFTER'!$A$2:$A$52,$A12) -> 5272510 | G12: =SUMIFS('Data AFTER'!$H$2:$H$52,'Data AFTER'!$A$2:$A$52,$A12) -> 6428153 | H12: =SUMIFS('Data AFTER'!$I$2:$I$52,'Data AFTER'!$A$2:$A$52,$A12) -> 8592 | I12: =SUMIFS('Data AFTER'!$J$2:$J$52,'Data AFTER'!$A$2:$A$52,$A12) -> 1088767 | J12: =IFERROR(G12/F12,"") -> 1.2191827 | K12: =IFERROR(D12/G12*1000,"") -> 0.23334852 | L12: =IFERROR(H12/G12,"") -> 0.0013366203 | M12: =IF(H12>0,D12/H12,"") -> 0.17458101 | N12: =IFERROR(I12/G12,"") -> 0.16937478 | O12: =IFERROR(D12/I12*1000,"") -> 1.3777052 | P12: =IFERROR(D12/F12*1000,"") -> 0.28449448
A13: Video views_July'2026 | B13: Video views | C13: =COUNTIFS('Data AFTER'!$A$2:$A$52,$A13) -> 2 | D13: =SUMIFS('Data AFTER'!$F$2:$F$52,'Data AFTER'!$A$2:$A$52,$A13) -> 1063.5 | E13: =D13/SUM('Data AFTER'!$F$2:$F$52) -> 0.043291506 | F13: =SUMIFS('Data AFTER'!$G$2:$G$52,'Data AFTER'!$A$2:$A$52,$A13) -> 3036460 | G13: =SUMIFS('Data AFTER'!$H$2:$H$52,'Data AFTER'!$A$2:$A$52,$A13) -> 3487246 | H13: =SUMIFS('Data AFTER'!$I$2:$I$52,'Data AFTER'!$A$2:$A$52,$A13) -> 10047 | I13: =SUMIFS('Data AFTER'!$J$2:$J$52,'Data AFTER'!$A$2:$A$52,$A13) -> 1389443 | J13: =IFERROR(G13/F13,"") -> 1.1484577 | K13: =IFERROR(D13/G13*1000,"") -> 0.30496845 | L13: =IFERROR(H13/G13,"") -> 0.00288107 | M13: =IF(H13>0,D13/H13,"") -> 0.10585249 | N13: =IFERROR(I13/G13,"") -> 0.39843561 | O13: =IFERROR(D13/I13*1000,"") -> 0.76541463 | P13: =IFERROR(D13/F13*1000,"") -> 0.35024338
A14: MCchicken_Reach_Sep'26 | B14: Reach | C14: =COUNTIFS('Data AFTER'!$A$2:$A$52,$A14) -> 1 | D14: =SUMIFS('Data AFTER'!$F$2:$F$52,'Data AFTER'!$A$2:$A$52,$A14) -> 852 | E14: =D14/SUM('Data AFTER'!$F$2:$F$52) -> 0.034682053 | F14: =SUMIFS('Data AFTER'!$G$2:$G$52,'Data AFTER'!$A$2:$A$52,$A14) -> 2503983 | G14: =SUMIFS('Data AFTER'!$H$2:$H$52,'Data AFTER'!$A$2:$A$52,$A14) -> 4583157 | H14: =SUMIFS('Data AFTER'!$I$2:$I$52,'Data AFTER'!$A$2:$A$52,$A14) -> 10719 | I14: =SUMIFS('Data AFTER'!$J$2:$J$52,'Data AFTER'!$A$2:$A$52,$A14) -> 1398142 | J14: =IFERROR(G14/F14,"") -> 1.8303467 | K14: =IFERROR(D14/G14*1000,"") -> 0.18589806 | L14: =IFERROR(H14/G14,"") -> 0.0023387809 | M14: =IF(H14>0,D14/H14,"") -> 0.079485027 | N14: =IFERROR(I14/G14,"") -> 0.3050609 | O14: =IFERROR(D14/I14*1000,"") -> 0.60938016 | P14: =IFERROR(D14/F14*1000,"") -> 0.3402579
A15: Grimace_Reach_July'26 | B15: Reach | C15: =COUNTIFS('Data AFTER'!$A$2:$A$52,$A15) -> 2 | D15: =SUMIFS('Data AFTER'!$F$2:$F$52,'Data AFTER'!$A$2:$A$52,$A15) -> 756.63 | E15: =D15/SUM('Data AFTER'!$F$2:$F$52) -> 0.030799861 | F15: =SUMIFS('Data AFTER'!$G$2:$G$52,'Data AFTER'!$A$2:$A$52,$A15) -> 3360139 | G15: =SUMIFS('Data AFTER'!$H$2:$H$52,'Data AFTER'!$A$2:$A$52,$A15) -> 3558936 | H15: =SUMIFS('Data AFTER'!$I$2:$I$52,'Data AFTER'!$A$2:$A$52,$A15) -> 7548 | I15: =SUMIFS('Data AFTER'!$J$2:$J$52,'Data AFTER'!$A$2:$A$52,$A15) -> 522459 | J15: =IFERROR(G15/F15,"") -> 1.0591633 | K15: =IFERROR(D15/G15*1000,"") -> 0.21260006 | L15: =IFERROR(H15/G15,"") -> 0.0021208586 | M15: =IF(H15>0,D15/H15,"") -> 0.10024245 | N15: =IFERROR(I15/G15,"") -> 0.14680202 | O15: =IFERROR(D15/I15*1000,"") -> 1.4482093 | P15: =IFERROR(D15/F15*1000,"") -> 0.22517818
A16: Opening_Nizami Mall | B16: Unlabelled (results ≠ reach) | C16: =COUNTIFS('Data AFTER'!$A$2:$A$52,$A16) -> 1 | D16: =SUMIFS('Data AFTER'!$F$2:$F$52,'Data AFTER'!$A$2:$A$52,$A16) -> 621.95 | E16: =D16/SUM('Data AFTER'!$F$2:$F$52) -> 0.025317491 | F16: =SUMIFS('Data AFTER'!$G$2:$G$52,'Data AFTER'!$A$2:$A$52,$A16) -> 1107096 | G16: =SUMIFS('Data AFTER'!$H$2:$H$52,'Data AFTER'!$A$2:$A$52,$A16) -> 2259715 | H16: =SUMIFS('Data AFTER'!$I$2:$I$52,'Data AFTER'!$A$2:$A$52,$A16) -> 1 | I16: =SUMIFS('Data AFTER'!$J$2:$J$52,'Data AFTER'!$A$2:$A$52,$A16) -> 776955 | J16: =IFERROR(G16/F16,"") -> 2.0411193 | K16: =IFERROR(D16/G16*1000,"") -> 0.27523382 | L16: =IFERROR(H16/G16,"") -> 4.4253368e-07 | M16: =IF(H16>0,D16/H16,"") -> 621.95 | N16: =IFERROR(I16/G16,"") -> 0.34382876 | O16: =IFERROR(D16/I16*1000,"") -> 0.80049681 | P16: =IFERROR(D16/F16*1000,"") -> 0.56178507
... A24: IOS_AppPromo_Chicken_AO_13043679488 | B24: App promotion | C24: =COUNTIFS('Data AFTER'!$A$2:$A$52,$A24) -> 1 | D24: =SUMIFS('Data AFTER'!$F$2:$F$52,'Data AFTER'!$A$2:$A$52,$A24) -> 0.02 | E24: =D24/SUM('Data AFTER'!$F$2:$F$52) -> 8.1413269e-07 | F24: =SUMIFS('Data AFTER'!$G$2:$G$52,'Data AFTER'!$A$2:$A$52,$A24) -> 24 | G24: =SUMIFS('Data AFTER'!$H$2:$H$52,'Data AFTER'!$A$2:$A$52,$A24) -> 29 | H24: =SUMIFS('Data AFTER'!$I$2:$I$52,'Data AFTER'!$A$2:$A$52,$A24) -> 0 | I24: =SUMIFS('Data AFTER'!$J$2:$J$52,'Data AFTER'!$A$2:$A$52,$A24) -> 4 | J24: =IFERROR(G24/F24,"") -> 1.2083333 | K24: =IFERROR(D24/G24*1000,"") -> 0.68965517 | L24: =IFERROR(H24/G24,"") -> 0 | M24: =IF(H24>0,D24/H24,"") | N24: =IFERROR(I24/G24,"") -> 0.13793103 | O24: =IFERROR(D24/I24*1000,"") -> 5 | P24: =IFERROR(D24/F24*1000,"") -> 0.83333333
A25: Total | C25: =SUM(C5:C24) -> 51 | D25: =SUM(D5:D24) -> 24566.02 | F25: =SUM(F5:F24) -> 61767357 | G25: =SUM(G5:G24) -> 93440992 | H25: =SUM(H5:H24) -> 204396 | I25: =SUM(I5:I24) -> 16912347

Sheet Ad Groups BEFORE
A1: Ad Groups BEFORE
A2: Ad group = (campaign, ad group) pair. BEFORE ad groups are one per campaign, named 'all'.
A4: Campaign | B4: Ad group | C4: Objective | D4: Ads | E4: Spend (USD) | F4: Share of spend | G4: Reach (ad level) | H4: Impressions | I4: Clicks | J4: 2-sec views | K4: Frequency (ad level) | L4: CPM (USD) | M4: CTR | N4: CPC (USD) | O4: 2-sec view rate | P4: Cost / 1K 2-sec views (USD) | Q4: Cost / 1K reached (USD)
A5: Reach_June'26 | B5: All | C5: Reach | D5: =COUNTIFS('Data BEFORE'!$A$2:$A$48,$A5,'Data BEFORE'!$B$2:$B$48,$B5) -> 24 | E5: =SUMIFS('Data BEFORE'!$F$2:$F$48,'Data BEFORE'!$A$2:$A$48,$A5,'Data BEFORE'!$B$2:$B$48,$B5) -> 10996.83 | F5: =E5/SUM('Data BEFORE'!$F$2:$F$48) -> 0.40346619 | G5: =SUMIFS('Data BEFORE'!$G$2:$G$48,'Data BEFORE'!$A$2:$A$48,$A5,'Data BEFORE'!$B$2:$B$48,$B5) -> 29728200 | H5: =SUMIFS('Data BEFORE'!$H$2:$H$48,'Data BEFORE'!$A$2:$A$48,$A5,'Data BEFORE'!$B$2:$B$48,$B5) -> 39701659 | I5: =SUMIFS('Data BEFORE'!$I$2:$I$48,'Data BEFORE'!$A$2:$A$48,$A5,'Data BEFORE'!$B$2:$B$48,$B5) -> 90529 | J5: =SUMIFS('Data BEFORE'!$J$2:$J$48,'Data BEFORE'!$A$2:$A$48,$A5,'Data BEFORE'!$B$2:$B$48,$B5) -> 9127912 | K5: =IFERROR(H5/G5,"") -> 1.3354882 | L5: =IFERROR(E5/H5*1000,"") -> 0.27698666 | M5: =IFERROR(I5/H5,"") -> 0.0022802322 | N5: =IF(I5>0,E5/I5,"") -> 0.12147301 | O5: =IFERROR(J5/H5,"") -> 0.22991261 | P5: =IFERROR(E5/J5*1000,"") -> 1.2047476 | Q5: =IFERROR(E5/G5*1000,"") -> 0.36991241
A6: Reach_April'26 | B6: all | C6: Reach | D6: =COUNTIFS('Data BEFORE'!$A$2:$A$48,$A6,'Data BEFORE'!$B$2:$B$48,$B6) -> 9 | E6: =SUMIFS('Data BEFORE'!$F$2:$F$48,'Data BEFORE'!$A$2:$A$48,$A6,'Data BEFORE'!$B$2:$B$48,$B6) -> 7000 | F6: =E6/SUM('Data BEFORE'!$F$2:$F$48) -> 0.25682522 | G6: =SUMIFS('Data BEFORE'!$G$2:$G$48,'Data BEFORE'!$A$2:$A$48,$A6,'Data BEFORE'!$B$2:$B$48,$B6) -> 14965894 | H6: =SUMIFS('Data BEFORE'!$H$2:$H$48,'Data BEFORE'!$A$2:$A$48,$A6,'Data BEFORE'!$B$2:$B$48,$B6) -> 26217754 | I6: =SUMIFS('Data BEFORE'!$I$2:$I$48,'Data BEFORE'!$A$2:$A$48,$A6,'Data BEFORE'!$B$2:$B$48,$B6) -> 74336 | J6: =SUMIFS('Data BEFORE'!$J$2:$J$48,'Data BEFORE'!$A$2:$A$48,$A6,'Data BEFORE'!$B$2:$B$48,$B6) -> 7168839 | K6: =IFERROR(H6/G6,"") -> 1.7518335 | L6: =IFERROR(E6/H6*1000,"") -> 0.26699465 | M6: =IFERROR(I6/H6,"") -> 0.0028353306 | N6: =IF(I6>0,E6/I6,"") -> 0.094167025 | O6: =IFERROR(J6/H6,"") -> 0.27343452 | P6: =IFERROR(E6/J6*1000,"") -> 0.97644821 | Q6: =IFERROR(E6/G6*1000,"") -> 0.46773016
A7: Reach_May'26 | B7: all | C7: Reach | D7: =COUNTIFS('Data BEFORE'!$A$2:$A$48,$A7,'Data BEFORE'!$B$2:$B$48,$B7) -> 8 | E7: =SUMIFS('Data BEFORE'!$F$2:$F$48,'Data BEFORE'!$A$2:$A$48,$A7,'Data BEFORE'!$B$2:$B$48,$B7) -> 7000 | F7: =E7/SUM('Data BEFORE'!$F$2:$F$48) -> 0.25682522 | G7: =SUMIFS('Data BEFORE'!$G$2:$G$48,'Data BEFORE'!$A$2:$A$48,$A7,'Data BEFORE'!$B$2:$B$48,$B7) -> 19665770 | H7: =SUMIFS('Data BEFORE'!$H$2:$H$48,'Data BEFORE'!$A$2:$A$48,$A7,'Data BEFORE'!$B$2:$B$48,$B7) -> 35530416 | I7: =SUMIFS('Data BEFORE'!$I$2:$I$48,'Data BEFORE'!$A$2:$A$48,$A7,'Data BEFORE'!$B$2:$B$48,$B7) -> 81684 | J7: =SUMIFS('Data BEFORE'!$J$2:$J$48,'Data BEFORE'!$A$2:$A$48,$A7,'Data BEFORE'!$B$2:$B$48,$B7) -> 6938421 | K7: =IFERROR(H7/G7,"") -> 1.8067137 | L7: =IFERROR(E7/H7*1000,"") -> 0.1970143 | M7: =IFERROR(I7/H7,"") -> 0.002298988 | N7: =IF(I7>0,E7/I7,"") -> 0.085696097 | O7: =IFERROR(J7/H7,"") -> 0.19528116 | P7: =IFERROR(E7/J7*1000,"") -> 1.0088751 | Q7: =IFERROR(E7/G7*1000,"") -> 0.35594843
A8: Community interaction_May'26 | B8: all | C8: Community interaction | D8: =COUNTIFS('Data BEFORE'!$A$2:$A$48,$A8,'Data BEFORE'!$B$2:$B$48,$B8) -> 2 | E8: =SUMIFS('Data BEFORE'!$F$2:$F$48,'Data BEFORE'!$A$2:$A$48,$A8,'Data BEFORE'!$B$2:$B$48,$B8) -> 1414.83 | F8: =E8/SUM('Data BEFORE'!$F$2:$F$48) -> 0.051909147 | G8: =SUMIFS('Data BEFORE'!$G$2:$G$48,'Data BEFORE'!$A$2:$A$48,$A8,'Data BEFORE'!$B$2:$B$48,$B8) -> 1011718 | H8: =SUMIFS('Data BEFORE'!$H$2:$H$48,'Data BEFORE'!$A$2:$A$48,$A8,'Data BEFORE'!$B$2:$B$48,$B8) -> 2906700 | I8: =SUMIFS('Data BEFORE'!$I$2:$I$48,'Data BEFORE'!$A$2:$A$48,$A8,'Data BEFORE'!$B$2:$B$48,$B8) -> 0 | J8: =SUMIFS('Data BEFORE'!$J$2:$J$48,'Data BEFORE'!$A$2:$A$48,$A8,'Data BEFORE'!$B$2:$B$48,$B8) -> 560362 | K8: =IFERROR(H8/G8,"") -> 2.8730338 | L8: =IFERROR(E8/H8*1000,"") -> 0.48674786 | M8: =IFERROR(I8/H8,"") -> 0 | N8: =IF(I8>0,E8/I8,"") | O8: =IFERROR(J8/H8,"") -> 0.19278288 | P8: =IFERROR(E8/J8*1000,"") -> 2.52485 | Q8: =IFERROR(E8/G8*1000,"") -> 1.398443
A9: Взаимодействие с сообществом20260611150844 | B9: Traffic_June'26 | C9: Community interaction | D9: =COUNTIFS('Data BEFORE'!$A$2:$A$48,$A9,'Data BEFORE'!$B$2:$B$48,$B9) -> 3 | E9: =SUMIFS('Data BEFORE'!$F$2:$F$48,'Data BEFORE'!$A$2:$A$48,$A9,'Data BEFORE'!$B$2:$B$48,$B9) -> 576.67 | F9: =E9/SUM('Data BEFORE'!$F$2:$F$48) -> 0.021157629 | G9: =SUMIFS('Data BEFORE'!$G$2:$G$48,'Data BEFORE'!$A$2:$A$48,$A9,'Data BEFORE'!$B$2:$B$48,$B9) -> 457234 | H9: =SUMIFS('Data BEFORE'!$H$2:$H$48,'Data BEFORE'!$A$2:$A$48,$A9,'Data BEFORE'!$B$2:$B$48,$B9) -> 741947 | I9: =SUMIFS('Data BEFORE'!$I$2:$I$48,'Data BEFORE'!$A$2:$A$48,$A9,'Data BEFORE'!$B$2:$B$48,$B9) -> 0 | J9: =SUMIFS('Data BEFORE'!$J$2:$J$48,'Data BEFORE'!$A$2:$A$48,$A9,'Data BEFORE'!$B$2:$B$48,$B9) -> 281859 | K9: =IFERROR(H9/G9,"") -> 1.6226855 | L9: =IFERROR(E9/H9*1000,"") -> 0.77723881 | M9: =IFERROR(I9/H9,"") -> 0 | N9: =IF(I9>0,E9/I9,"") | O9: =IFERROR(J9/H9,"") -> 0.37989102 | P9: =IFERROR(E9/J9*1000,"") -> 2.0459521 | Q9: =IFERROR(E9/G9*1000,"") -> 1.2612142
A10: Community_int_generic_22.04 | B10: generic_22.04 | C10: Community interaction | D10: =COUNTIFS('Data BEFORE'!$A$2:$A$48,$A10,'Data BEFORE'!$B$2:$B$48,$B10) -> 1 | E10: =SUMIFS('Data BEFORE'!$F$2:$F$48,'Data BEFORE'!$A$2:$A$48,$A10,'Data BEFORE'!$B$2:$B$48,$B10) -> 267.56 | F10: =E10/SUM('Data BEFORE'!$F$2:$F$48) -> 0.0098165938 | G10: =SUMIFS('Data BEFORE'!$G$2:$G$48,'Data BEFORE'!$A$2:$A$48,$A10,'Data BEFORE'!$B$2:$B$48,$B10) -> 146099 | H10: =SUMIFS('Data BEFORE'!$H$2:$H$48,'Data BEFORE'!$A$2:$A$48,$A10,'Data BEFORE'!$B$2:$B$48,$B10) -> 258263 | I10: =SUMIFS('Data BEFORE'!$I$2:$I$48,'Data BEFORE'!$A$2:$A$48,$A10,'Data BEFORE'!$B$2:$B$48,$B10) -> 0 | J10: =SUMIFS('Data BEFORE'!$J$2:$J$48,'Data BEFORE'!$A$2:$A$48,$A10,'Data BEFORE'!$B$2:$B$48,$B10) -> 66068 | K10: =IFERROR(H10/G10,"") -> 1.767726 | L10: =IFERROR(E10/H10*1000,"") -> 1.0359982 | M10: =IFERROR(I10/H10,"") -> 0 | N10: =IF(I10>0,E10/I10,"") | O10: =IFERROR(J10/H10,"") -> 0.25581674 | P10: =IFERROR(E10/J10*1000,"") -> 4.0497669 | Q10: =IFERROR(E10/G10*1000,"") -> 1.8313609
A11: Total | D11: =SUM(D5:D10) -> 47 | E11: =SUM(E5:E10) -> 27255.89 | G11: =SUM(G5:G10) -> 65974915 | H11: =SUM(H5:H10) -> 105356739 | I11: =SUM(I5:I10) -> 246549 | J11: =SUM(J5:J10) -> 24143461

Sheet Ad Groups AFTER
A1: Ad Groups AFTER
A2: Ad group = (campaign, ad group) pair. BEFORE ad groups are one per campaign, named 'all'.
A4: Campaign | B4: Ad group | C4: Objective | D4: Ads | E4: Spend (USD) | F4: Share of spend | G4: Reach (ad level) | H4: Impressions | I4: Clicks | J4: 2-sec views | K4: Frequency (ad level) | L4: CPM (USD) | M4: CTR | N4: CPC (USD) | O4: 2-sec view rate | P4: Cost / 1K 2-sec views (USD) | Q4: Cost / 1K reached (USD)
A5: MCchicken_Reach_July'26 | B5: MC_Value_03.06 | C5: Reach | D5: =COUNTIFS('Data AFTER'!$A$2:$A$52,$A5,'Data AFTER'!$B$2:$B$52,$B5) -> 1 | E5: =SUMIFS('Data AFTER'!$F$2:$F$52,'Data AFTER'!$A$2:$A$52,$A5,'Data AFTER'!$B$2:$B$52,$B5) -> 3594.01 | F5: =E5/SUM('Data AFTER'!$F$2:$F$52) -> 0.14630005 | G5: =SUMIFS('Data AFTER'!$G$2:$G$52,'Data AFTER'!$A$2:$A$52,$A5,'Data AFTER'!$B$2:$B$52,$B5) -> 3359491 | H5: =SUMIFS('Data AFTER'!$H$2:$H$52,'Data AFTER'!$A$2:$A$52,$A5,'Data AFTER'!$B$2:$B$52,$B5) -> 11212822 | I5: =SUMIFS('Data AFTER'!$I$2:$I$52,'Data AFTER'!$A$2:$A$52,$A5,'Data AFTER'!$B$2:$B$52,$B5) -> 26184 | J5: =SUMIFS('Data AFTER'!$J$2:$J$52,'Data AFTER'!$A$2:$A$52,$A5,'Data AFTER'!$B$2:$B$52,$B5) -> 799143 | K5: =IFERROR(H5/G5,"") -> 3.337655 | L5: =IFERROR(E5/H5*1000,"") -> 0.3205268 | M5: =IFERROR(I5/H5,"") -> 0.0023351838 | N5: =IF(I5>0,E5/I5,"") -> 0.13725978 | O5: =IFERROR(J5/H5,"") -> 0.071270462 | P5: =IFERROR(E5/J5*1000,"") -> 4.4973303 | Q5: =IFERROR(E5/G5*1000,"") -> 1.0698079
A6: FIFA_Reach_July'26 | B6: Fifa_reach_18-50 | C6: Reach | D6: =COUNTIFS('Data AFTER'!$A$2:$A$52,$A6,'Data AFTER'!$B$2:$B$52,$B6) -> 6 | E6: =SUMIFS('Data AFTER'!$F$2:$F$52,'Data AFTER'!$A$2:$A$52,$A6,'Data AFTER'!$B$2:$B$52,$B6) -> 3110 | F6: =E6/SUM('Data AFTER'!$F$2:$F$52) -> 0.12659763 | G6: =SUMIFS('Data AFTER'!$G$2:$G$52,'Data AFTER'!$A$2:$A$52,$A6,'Data AFTER'!$B$2:$B$52,$B6) -> 8956075 | H6: =SUMIFS('Data AFTER'!$H$2:$H$52,'Data AFTER'!$A$2:$A$52,$A6,'Data AFTER'!$B$2:$B$52,$B6) -> 10446178 | I6: =SUMIFS('Data AFTER'!$I$2:$I$52,'Data AFTER'!$A$2:$A$52,$A6,'Data AFTER'!$B$2:$B$52,$B6) -> 22490 | J6: =SUMIFS('Data AFTER'!$J$2:$J$52,'Data AFTER'!$A$2:$A$52,$A6,'Data AFTER'!$B$2:$B$52,$B6) -> 2692310 | K6: =IFERROR(H6/G6,"") -> 1.166379 | L6: =IFERROR(E6/H6*1000,"") -> 0.29771654 | M6: =IFERROR(I6/H6,"") -> 0.0021529405 | N6: =IF(I6>0,E6/I6,"") -> 0.13828368 | O6: =IFERROR(J6/H6,"") -> 0.25773158 | P6: =IFERROR(E6/J6*1000,"") -> 1.1551419 | Q6: =IFERROR(E6/G6*1000,"") -> 0.34725033
A7: McCafe_Reach_Sep_26 | B7: Core TA | C7: Reach | D7: =COUNTIFS('Data AFTER'!$A$2:$A$52,$A7,'Data AFTER'!$B$2:$B$52,$B7) -> 2 | E7: =SUMIFS('Data AFTER'!$F$2:$F$52,'Data AFTER'!$A$2:$A$52,$A7,'Data AFTER'!$B$2:$B$52,$B7) -> 2730.67 | F7: =E7/SUM('Data AFTER'!$F$2:$F$52) -> 0.11115639 | G7: =SUMIFS('Data AFTER'!$G$2:$G$52,'Data AFTER'!$A$2:$A$52,$A7,'Data AFTER'!$B$2:$B$52,$B7) -> 4332171 | H7: =SUMIFS('Data AFTER'!$H$2:$H$52,'Data AFTER'!$A$2:$A$52,$A7,'Data AFTER'!$B$2:$B$52,$B7) -> 11665942 | I7: =SUMIFS('Data AFTER'!$I$2:$I$52,'Data AFTER'!$A$2:$A$52,$A7,'Data AFTER'!$B$2:$B$52,$B7) -> 27096 | J7: =SUMIFS('Data AFTER'!$J$2:$J$52,'Data AFTER'!$A$2:$A$52,$A7,'Data AFTER'!$B$2:$B$52,$B7) -> 806808 | K7: =IFERROR(H7/G7,"") -> 2.6928628 | L7: =IFERROR(E7/H7*1000,"") -> 0.23407197 | M7: =IFERROR(I7/H7,"") -> 0.0023226586 | N7: =IF(I7>0,E7/I7,"") -> 0.10077761 | O7: =IFERROR(J7/H7,"") -> 0.069159267 | P7: =IFERROR(E7/J7*1000,"") -> 3.3845351 | Q7: =IFERROR(E7/G7*1000,"") -> 0.63032369
A8: Mixology_Reach_July'26 | B8: Mixology_Launch_03.06 | C8: Reach | D8: =COUNTIFS('Data AFTER'!$A$2:$A$52,$A8,'Data AFTER'!$B$2:$B$52,$B8) -> 6 | E8: =SUMIFS('Data AFTER'!$F$2:$F$52,'Data AFTER'!$A$2:$A$52,$A8,'Data AFTER'!$B$2:$B$52,$B8) -> 2339 | F8: =E8/SUM('Data AFTER'!$F$2:$F$52) -> 0.095212818 | G8: =SUMIFS('Data AFTER'!$G$2:$G$52,'Data AFTER'!$A$2:$A$52,$A8,'Data AFTER'!$B$2:$B$52,$B8) -> 8477218 | H8: =SUMIFS('Data AFTER'!$H$2:$H$52,'Data AFTER'!$A$2:$A$52,$A8,'Data AFTER'!$B$2:$B$52,$B8) -> 9454513 | I8: =SUMIFS('Data AFTER'!$I$2:$I$52,'Data AFTER'!$A$2:$A$52,$A8,'Data AFTER'!$B$2:$B$52,$B8) -> 23069 | J8: =SUMIFS('Data AFTER'!$J$2:$J$52,'Data AFTER'!$A$2:$A$52,$A8,'Data AFTER'!$B$2:$B$52,$B8) -> 1384300 | K8: =IFERROR(H8/G8,"") -> 1.1152849 | L8: =IFERROR(E8/H8*1000,"") -> 0.24739508 | M8: =IFERROR(I8/H8,"") -> 0.0024399988 | N8: =IF(I8>0,E8/I8,"") -> 0.10139148 | O8: =IFERROR(J8/H8,"") -> 0.14641685 | P8: =IFERROR(E8/J8*1000,"") -> 1.6896626 | Q8: =IFERROR(E8/G8*1000,"") -> 0.27591599
A9: HM_Reach_Sep'26 | B9: Parents | C9: Reach | D9: =COUNTIFS('Data AFTER'!$A$2:$A$52,$A9,'Data AFTER'!$B$2:$B$52,$B9) -> 2 | E9: =SUMIFS('Data AFTER'!$F$2:$F$52,'Data AFTER'!$A$2:$A$52,$A9,'Data AFTER'!$B$2:$B$52,$B9) -> 1543 | F9: =E9/SUM('Data AFTER'!$F$2:$F$52) -> 0.062810337 | G9: =SUMIFS('Data AFTER'!$G$2:$G$52,'Data AFTER'!$A$2:$A$52,$A9,'Data AFTER'!$B$2:$B$52,$B9) -> 2614678 | H9: =SUMIFS('Data AFTER'!$H$2:$H$52,'Data AFTER'!$A$2:$A$52,$A9,'Data AFTER'!$B$2:$B$52,$B9) -> 3966708 | I9: =SUMIFS('Data AFTER'!$I$2:$I$52,'Data AFTER'!$A$2:$A$52,$A9,'Data AFTER'!$B$2:$B$52,$B9) -> 11510 | J9: =SUMIFS('Data AFTER'!$J$2:$J$52,'Data AFTER'!$A$2:$A$52,$A9,'Data AFTER'!$B$2:$B$52,$B9) -> 550513 | K9: =IFERROR(H9/G9,"") -> 1.5170924 | L9: =IFERROR(E9/H9*1000,"") -> 0.38898754 | M9: =IFERROR(I9/H9,"") -> 0.0029016504 | N9: =IF(I9>0,E9/I9,"") -> 0.13405734 | O9: =IFERROR(J9/H9,"") -> 0.13878334 | P9: =IFERROR(E9/J9*1000,"") -> 2.8028403 | Q9: =IFERROR(E9/G9*1000,"") -> 0.59013003
A10: Mixology_Reach_Aug'26 | B10: Mixology_Launch_01.07 | C10: Reach | D10: =COUNTIFS('Data AFTER'!$A$2:$A$52,$A10,'Data AFTER'!$B$2:$B$52,$B10) -> 3 | E10: =SUMIFS('Data AFTER'!$F$2:$F$52,'Data AFTER'!$A$2:$A$52,$A10,'Data AFTER'!$B$2:$B$52,$B10) -> 1507.38 | F10: =E10/SUM('Data AFTER'!$F$2:$F$52) -> 0.061360367 | G10: =SUMIFS('Data AFTER'!$G$2:$G$52,'Data AFTER'!$A$2:$A$52,$A10,'Data AFTER'!$B$2:$B$52,$B10) -> 4122062 | H10: =SUMIFS('Data AFTER'!$H$2:$H$52,'Data AFTER'!$A$2:$A$52,$A10,'Data AFTER'!$B$2:$B$52,$B10) -> 7112181 | I10: =SUMIFS('Data AFTER'!$I$2:$I$52,'Data AFTER'!$A$2:$A$52,$A10,'Data AFTER'!$B$2:$B$52,$B10) -> 17250 | J10: =SUMIFS('Data AFTER'!$J$2:$J$52,'Data AFTER'!$A$2:$A$52,$A10,'Data AFTER'!$B$2:$B$52,$B10) -> 772328 | K10: =IFERROR(H10/G10,"") -> 1.725394 | L10: =IFERROR(E10/H10*1000,"") -> 0.21194342 | M10: =IFERROR(I10/H10,"") -> 0.0024254163 | N10: =IF(I10>0,E10/I10,"") -> 0.087384348 | O10: =IFERROR(J10/H10,"") -> 0.10859229 | P10: =IFERROR(E10/J10*1000,"") -> 1.9517355 | Q10: =IFERROR(E10/G10*1000,"") -> 0.36568591
